Workbook
Name \A: [1]Isian!#REF!
Name \B: [1]Isian!#REF!
Name \C: [1]Isian!#REF!
Name \D: [1]Isian!#REF!
Name \E: [1]Isian!#REF!
Name \F: [1]Isian!#REF!
Name \G: [1]Isian!#REF!
Name \H: [1]Isian!#REF!
Name \I: [1]Isian!#REF!
Name \J: [1]Isian!#REF!
Name \V: #REF!
Name \X: #REF!
Name \Z: #REF!
Name _____bpp1: [2]gl!$E$322
Name _____bpp2: #REF!
Name _____bpp3: #REF!
Name ____bpp1: [2]gl!$E$322
Name ____bpp2: #REF!
Name ____bpp3: #REF!
Name ___bpp1: [2]gl!$E$322
Name ___bpp2: #REF!
Name ___bpp3: #REF!
Name __bpp1: [2]gl!$E$322
Name __bpp2: #REF!
Name __bpp3: #REF!
Name _1: #REF!
Name _1195.A1: #REF!
Name _1195.A2: #REF!
Name _1195.A3: #REF!
Name _1195.B1: '[4]1195 B1'!#REF!
Name _1195.B11: '[5]1195 B1'!#REF!
Name _1195.B2: #REF!
Name _1195.B4: #REF!
Name _1195a: [6]Identitas!#REF!
Name _1195c: #REF!
Name _31_12_1993: #REF!
Name _Apr01: #REF!
Name _B_BNI.6064.Pro: #REF!
Name _bdn01: #REF!
Name _bp01: [7]BP1_23!#REF!
Name _bpp1: [2]gl!$E$322
Name _bpp2: #REF!
Name _bpp3: #REF!
Name _CTM13: #REF!
Name _CTM15: #REF!
Name _CTM18: #REF!
Name _CTM23: #REF!
Name _CTM26: #REF!
Name _CTM38: #REF!
Name _CTM7: #REF!
Name _DAF_ISI: #REF!
Name _Data.umum: #REF!
Name _DENGAN_PERBAND: [8]NERACA!#REF!
Name _fp01: #REF!
Name _HIT01: #REF!
Name _jan01: #REF!
Name _MTL13: #REF!
Name _MTL15: #REF!
Name _MTL18: #REF!
Name _MTL23: #REF!

Sheet User
C6: KODE | D6: GL-2468907531-XCL

Sheet Menu
B5: Nama Perusahaan | C5: ARYA USAHA TIRTA, CV
B6: Tahun | C6: 2026

Sheet Akun
A1: =NAMA -> ARYA USAHA TIRTA, CV
A2: DAFTAR AKUN
A3: ="Tahun : "&THN -> Tahun : 2026
A5: Kode | B5: Nama Akun | C5: Pos | D5: Pos | F5: Saldo Awal | G5: Saldo Awal
A6: Akun | C6: Saldo | D6: Laporan | F6: Debet | G6: Kredit
A7: 100000000 | B7: AKTIVA
A8: 1-100-000 | B8: AKTIVA LANCAR
A9: 1-101-000 | B9: Kas dan Bank | C9: Db | D9: NRC
A10: 1-101-001 | B10: Petty Cash | C10: Db | D10: NRC | F10: 0
A11: 1-101-010 | B11: CIMB Niaga - Acc. No: 800171592300 | C11: Db | D11: NRC | F11: 3043241
A12: 1-101-011 | B12: Bank 2 | C12: Db | D12: NRC | F12: 0
A13: 1-101-012 | B13: Bank 3 | C13: Db | D13: NRC | F13: 0
A14: 1-101-013 | B14: BAnk 4 | C14: Db | D14: NRC | F14: 0
A15: 1-101-100 | B15: Bank Deposit | C15: Db | D15: NRC | F15: 0
A16: 1-101-101 | B16: Others Deposit | C16: Db | D16: NRC | F16: 0
A17: 1-101-200 | B17: Cash In Transit | C17: Db | D17: NRC | F17: 0
A18: 1-102-000 | B18: Account Receivable | C18: Db | D18: NRC | F18: 0
A19: 1-102-001 | B19: Receivable - Trade | C19: Db | D19: NRC | F19: 13548978
A20: 1-102-002 | B20: Employee Receivable | C20: Db | D20: NRC | F20: 0
A21: 1-102-003 | B21: Prepayment / Uang Muka | C21: Db | D21: NRC | F21: 0
... A53: 1-120-999 | B53: Other Asset | C53: Db | D53: NRC | F53: 0
A54: 2-130-000 | B54: Account Payable | C54: Kr | D54: NRC | G54: 0
A55: 2-130-001 | B55: Account Payable - Trade | C55: Kr | D55: NRC | G55: 0
A56: 2-140-000 | B56: Other Payable | C56: Kr | D56: NRC | G56: 0
A57: 2-140-001 | B57: Salary Payable | C57: Kr | D57: NRC | G57: 0
A58: 2-140-010 | B58: BPJS Payable | C58: Kr | D58: NRC | G58: 0
A59: 2-140-020 | B59: Accrued Expenses - General | C59: Kr | D59: NRC | G59: 0
A60: 2-140-021 | B60: Accrued Expenses - Project | C60: Kr | D60: NRC | G60: 0
A61: 2-140-030 | B61: Tax Payable - PPh Ps 21/26 | C61: Kr | D61: NRC | G61: 0
A62: 2-140-031 | B62: Tax Payable - PPh Ps 23 | C62: Kr | D62: NRC | G62: 0
A63: 2-140-032 | B63: Tax Payable - PPh Ps 29 | C63: Kr | D63: NRC | G63: 0
A64: 2-140-033 | B64: Tax Payable - PPh Ps 4 (2) | C64: Kr | D64: NRC | G64: 0
A65: 2-140-040 | B65: Dividend Payable | C65: Kr | D65: NRC | G65: 0
... A88: 3-102-004 | B88: Ekuitas Lainnya | C88: Kr | D88: LR | G88: 19663808
A89: 4-100-000 | B89: Total Revenue | C89: Kr | D89: LR
A90: 4-101-000 | B90: Total Event Management Services Income | C90: Kr | D90: LR
A91: 4-101-001 | B91: Pendapatan Usaha | C91: Kr | D91: LR
A92: 4-101-002 | B92: Pendapatan .... | C92: Kr | D92: LR
A93: 4-101-003 | B93: Pendapatan .... | C93: Kr | D93: LR
A94: 4-101-004 | B94: Pendapatan .... | C94: Kr | D94: LR
...

Sheet Kode
A1: =NAMA -> ARYA USAHA TIRTA, CV
A2: DAFTAR KODE PEMBANTU
A3: ="Tahun : "&THN -> Tahun : 2026
A5: Kode | B5: Piutang Dagang | C5: Status | D5: Saldo Awal
B14: Jumlah | D14: =SUM(D6:D13) -> 0
A17: Kode | B17: Piutang Lain-lain | C17: Status | D17: Saldo Awal
A18: CT-001 | B18: Jaya Impian Abadi | C18: Piutang | D18: 0
A19: CT-002 | B19: Arya Usaha Tirta | C19: Piutang | D19: 0
A20: CT-003 | C20: Piutang | D20: 0
A21: SH-001 | B21: Jilmi Astina Anif | C21: Piutang | D21: 0
A22: SH-002 | B22: Arief Yudo Wibowo | C22: Piutang | D22: 0
A23: SH-003 | B23: Djulianis | C23: Piutang | D23: 0
A24: SH-004 | B24: Yanita | C24: Piutang | D24: 0
C25: Piutang | D25: 0
C26: Piutang | D26: 0
B27: Jumlah | D27: =SUM(D18:D26) -> 0
A30: Kode | B30: Hutang Dagang | C30: Status | D30: Saldo Awal
A31: AP-001 | B31: KMK BRI | C31: Hutang | D31: 0
A32: AP-002 | B32: GIFTEE | C32: Hutang | D32: 0
C33: Hutang | D33: 0
C34: Hutang | D34: 0
C35: Hutang | D35: 0
B38: Jumlah | D38: =SUM(D31:D37) -> 0

Sheet Jurnal
F1: =NAMA -> ARYA USAHA TIRTA, CV
F2: JURNAL UMUM
F3: ="Tahun : "&THN -> Tahun : 2026
L4: =SUM(L7:L1000) -> 310838800 | M4: =SUM(M7:M1000) -> 310838800 | N4: =L4-M4 -> 0
F5: Tanggal | G5: Bukti | H5: Keterangan Transaksi | I5: Kode | J5: Nama Akun | K5: Kode | L5: Debet | M5: Kredit
A6: 1 | B6: 2 | C6: 3 | D6: 4 | I6: Akun | K6: Bantu
A7: =IF(I7=VALUE,VALUE,COUNTIF($B$7:B7,B7))&I7&IF(F7<>VALUE,TEXT(F7,"mmmm"),VALUE) -> 00 | B7: =I7&IF(F7<>VALUE,TEXT(F7,"mmmm"),VALUE) -> 0 | C7: =COUNTIF($K$7:K7,K7)&K7 -> 0 | D7: =IF(MONTH(F7)<MONTH(BLN),"1"&I7,VALUE) -> 1 | J7: =IF(ISNA(VLOOKUP(I7,DAF_AKUN,2,FALSE)),"-",VLOOKUP(I7,DAF_AKUN,2,FALSE)) -> -
A8: =IF(I8=VALUE,VALUE,COUNTIF($B$7:B8,B8))&I8&IF(F8<>VALUE,TEXT(F8,"mmmm"),VALUE) -> 00 | B8: =I8&IF(F8<>VALUE,TEXT(F8,"mmmm"),VALUE) -> 0 | C8: =COUNTIF($K$7:K8,K8)&K8 -> 0 | D8: =IF(MONTH(F8)<MONTH(BLN),"1"&I8,VALUE) -> 1 | H8: Sales | J8: =IF(ISNA(VLOOKUP(I8,DAF_AKUN,2,FALSE)),"-",VLOOKUP(I8,DAF_AKUN,2,FALSE)) -> -
A9: =IF(I9=VALUE,VALUE,COUNTIF($B$7:B9,B9))&I9&IF(F9<>VALUE,TEXT(F9,"mmmm"),VALUE) -> 11-102-001January | B9: =I9&IF(F9<>VALUE,TEXT(F9,"mmmm"),VALUE) -> 1-102-001January | C9: =COUNTIF($K$7:K9,K9)&K9 -> 0 | D9: =IF(MONTH(F9)<MONTH(BLN),"1"&I9,VALUE) -> 11-102-001 | F9: 46053 | H9: Sales Januari 2026 | I9: 1-102-001 | J9: =IF(ISNA(VLOOKUP(I9,DAF_AKUN,2,FALSE)),"-",VLOOKUP(I9,DAF_AKUN,2,FALSE)) -> Receivable - Trade | L9: =SUM(M10:M18) -> 20321000
A10: =IF(I10=VALUE,VALUE,COUNTIF($B$7:B10,B10))&I10&IF(F10<>VALUE,TEXT(F10,"mmmm"),VALUE) -> 14-101-001January | B10: =I10&IF(F10<>VALUE,TEXT(F10,"mmmm"),VALUE) -> 4-101-001January | C10: =COUNTIF($K$7:K10,K10)&K10 -> 0 | D10: =IF(MONTH(F10)<MONTH(BLN),"1"&I10,VALUE) -> 14-101-001 | F10: 46030 | G10: INV-00196 | H10: Paviliun Date 9-13 Jan | I10: 4-101-001 | J10: =IF(ISNA(VLOOKUP(I10,DAF_AKUN,2,FALSE)),"-",VLOOKUP(I10,DAF_AKUN,2,FALSE)) -> Pendapatan Usaha | M10: 1960000
A11: =IF(I11=VALUE,VALUE,COUNTIF($B$7:B11,B11))&I11&IF(F11<>VALUE,TEXT(F11,"mmmm"),VALUE) -> 24-101-001January | B11: =I11&IF(F11<>VALUE,TEXT(F11,"mmmm"),VALUE) -> 4-101-001January | C11: =COUNTIF($K$7:K11,K11)&K11 -> 0 | D11: =IF(MONTH(F11)<MONTH(BLN),"1"&I11,VALUE) -> 14-101-001 | F11: 46034 | G11: INV-001100 | H11: Surfing Lesson | I11: 4-101-001 | J11: =IF(ISNA(VLOOKUP(I11,DAF_AKUN,2,FALSE)),"-",VLOOKUP(I11,DAF_AKUN,2,FALSE)) -> Pendapatan Usaha | M11: 4060000
A12: =IF(I12=VALUE,VALUE,COUNTIF($B$7:B12,B12))&I12&IF(F12<>VALUE,TEXT(F12,"mmmm"),VALUE) -> 34-101-001January | B12: =I12&IF(F12<>VALUE,TEXT(F12,"mmmm"),VALUE) -> 4-101-001January | C12: =COUNTIF($K$7:K12,K12)&K12 -> 0 | D12: =IF(MONTH(F12)<MONTH(BLN),"1"&I12,VALUE) -> 14-101-001 | F12: 46034 | G12: INV-001101 | H12: Room 3 | I12: 4-101-001 | J12: =IF(ISNA(VLOOKUP(I12,DAF_AKUN,2,FALSE)),"-",VLOOKUP(I12,DAF_AKUN,2,FALSE)) -> Pendapatan Usaha | M12: 2500000
A13: =IF(I13=VALUE,VALUE,COUNTIF($B$7:B13,B13))&I13&IF(F13<>VALUE,TEXT(F13,"mmmm"),VALUE) -> 44-101-001January | B13: =I13&IF(F13<>VALUE,TEXT(F13,"mmmm"),VALUE) -> 4-101-001January | C13: =COUNTIF($K$7:K13,K13)&K13 -> 0 | D13: =IF(MONTH(F13)<MONTH(BLN),"1"&I13,VALUE) -> 14-101-001 | F13: 46036 | G13: INV-001102 | H13: Room 2 | I13: 4-101-001 | J13: =IF(ISNA(VLOOKUP(I13,DAF_AKUN,2,FALSE)),"-",VLOOKUP(I13,DAF_AKUN,2,FALSE)) -> Pendapatan Usaha | M13: 1400000
A14: =IF(I14=VALUE,VALUE,COUNTIF($B$7:B14,B14))&I14&IF(F14<>VALUE,TEXT(F14,"mmmm"),VALUE) -> 54-101-001January | B14: =I14&IF(F14<>VALUE,TEXT(F14,"mmmm"),VALUE) -> 4-101-001January | C14: =COUNTIF($K$7:K14,K14)&K14 -> 0 | D14: =IF(MONTH(F14)<MONTH(BLN),"1"&I14,VALUE) -> 14-101-001 | F14: 46036 | G14: INV-001102 | H14: Room 2 | I14: 4-101-001 | J14: =IF(ISNA(VLOOKUP(I14,DAF_AKUN,2,FALSE)),"-",VLOOKUP(I14,DAF_AKUN,2,FALSE)) -> Pendapatan Usaha | M14: 721000
A15: =IF(I15=VALUE,VALUE,COUNTIF($B$7:B775,B15))&I15&IF(F15<>VALUE,TEXT(F15,"mmmm"),VALUE) -> 104-101-001January | B15: =I15&IF(F15<>VALUE,TEXT(F15,"mmmm"),VALUE) -> 4-101-001January | C15: =COUNTIF($K$7:K775,K15)&K15 -> 0 | D15: =IF(MONTH(F15)<MONTH(BLN),"1"&I15,VALUE) -> 14-101-001 | F15: 46041 | G15: INV-001104 | H15: Bike Rent | I15: 4-101-001 | J15: =IF(ISNA(VLOOKUP(I15,DAF_AKUN,2,FALSE)),"-",VLOOKUP(I15,DAF_AKUN,2,FALSE)) -> Pendapatan Usaha | M15: 560000
A16: =IF(I16=VALUE,VALUE,COUNTIF($B$7:B16,B16))&I16&IF(F16<>VALUE,TEXT(F16,"mmmm"),VALUE) -> 74-101-001January | B16: =I16&IF(F16<>VALUE,TEXT(F16,"mmmm"),VALUE) -> 4-101-001January | C16: =COUNTIF($K$7:K16,K16)&K16 -> 0 | D16: =IF(MONTH(F16)<MONTH(BLN),"1"&I16,VALUE) -> 14-101-001 | F16: 46041 | G16: INV-001103 | H16: Room 3 | I16: 4-101-001 | J16: =IF(ISNA(VLOOKUP(I16,DAF_AKUN,2,FALSE)),"-",VLOOKUP(I16,DAF_AKUN,2,FALSE)) -> Pendapatan Usaha | M16: 4120000
A17: =IF(I17=VALUE,VALUE,COUNTIF($B$7:B775,B17))&I17&IF(F17<>VALUE,TEXT(F17,"mmmm"),VALUE) -> 104-101-001January | B17: =I17&IF(F17<>VALUE,TEXT(F17,"mmmm"),VALUE) -> 4-101-001January | C17: =COUNTIF($K$7:K775,K17)&K17 -> 0 | D17: =IF(MONTH(F17)<MONTH(BLN),"1"&I17,VALUE) -> 14-101-001 | F17: 46041 | G17: INV-001105 | H17: Room 2 | I17: 4-101-001 | J17: =IF(ISNA(VLOOKUP(I17,DAF_AKUN,2,FALSE)),"-",VLOOKUP(I17,DAF_AKUN,2,FALSE)) -> Pendapatan Usaha | M17: 1500000
A18: =IF(I18=VALUE,VALUE,COUNTIF($B$7:B163,B18))&I18&IF(F18<>VALUE,TEXT(F18,"mmmm"),VALUE) -> 104-101-001January | B18: =I18&IF(F18<>VALUE,TEXT(F18,"mmmm"),VALUE) -> 4-101-001January | C18: =COUNTIF($K$7:K163,K18)&K18 -> 0 | D18: =IF(MONTH(F18)<MONTH(BLN),"1"&I18,VALUE) -> 14-101-001 | F18: 46042 | G18: INV-001106 | H18: Room 1 | I18: 4-101-001 | J18: =IF(ISNA(VLOOKUP(I18,DAF_AKUN,2,FALSE)),"-",VLOOKUP(I18,DAF_AKUN,2,FALSE)) -> Pendapatan Usaha | M18: 3500000
A19: =IF(I19=VALUE,VALUE,COUNTIF($B$7:B19,B19))&I19&IF(F19<>VALUE,TEXT(F19,"mmmm"),VALUE) -> 11-102-001February | B19: =I19&IF(F19<>VALUE,TEXT(F19,"mmmm"),VALUE) -> 1-102-001February | C19: =COUNTIF($K$7:K19,K19)&K19 -> 0 | D19: =IF(MONTH(F19)<MONTH(BLN),"1"&I19,VALUE) -> 11-102-001 | F19: 46081 | H19: Sales Februari 2026 | I19: 1-102-001 | J19: =IF(ISNA(VLOOKUP(I19,DAF_AKUN,2,FALSE)),"-",VLOOKUP(I19,DAF_AKUN,2,FALSE)) -> Receivable - Trade | L19: =SUM(M20:M26) -> 16850000
A20: =IF(I20=VALUE,VALUE,COUNTIF($B$7:B20,B20))&I20&IF(F20<>VALUE,TEXT(F20,"mmmm"),VALUE) -> 14-101-001February | B20: =I20&IF(F20<>VALUE,TEXT(F20,"mmmm"),VALUE) -> 4-101-001February | C20: =COUNTIF($K$7:K20,K20)&K20 -> 0 | D20: =IF(MONTH(F20)<MONTH(BLN),"1"&I20,VALUE) -> 14-101-001 | F20: 46058 | G20: INV-00113 | H20: Room 4 | I20: 4-101-001 | J20: =IF(ISNA(VLOOKUP(I20,DAF_AKUN,2,FALSE)),"-",VLOOKUP(I20,DAF_AKUN,2,FALSE)) -> Pendapatan Usaha | M20: 4500000
A21: =IF(I21=VALUE,VALUE,COUNTIF($B$7:B21,B21))&I21&IF(F21<>VALUE,TEXT(F21,"mmmm"),VALUE) -> 24-101-001February | B21: =I21&IF(F21<>VALUE,TEXT(F21,"mmmm"),VALUE) -> 4-101-001February | C21: =COUNTIF($K$7:K21,K21)&K21 -> 0 | D21: =IF(MONTH(F21)<MONTH(BLN),"1"&I21,VALUE) -> 14-101-001 | F21: 46058 | G21: INV-00114 | H21: Room 6 | I21: 4-101-001 | J21: =IF(ISNA(VLOOKUP(I21,DAF_AKUN,2,FALSE)),"-",VLOOKUP(I21,DAF_AKUN,2,FALSE)) -> Pendapatan Usaha | M21: 1600000
A22: =IF(I22=VALUE,VALUE,COUNTIF($B$7:B22,B22))&I22&IF(F22<>VALUE,TEXT(F22,"mmmm"),VALUE) -> 34-101-001February | B22: =I22&IF(F22<>VALUE,TEXT(F22,"mmmm"),VALUE) -> 4-101-001February | C22: =COUNTIF($K$7:K22,K22)&K22 -> 0 | D22: =IF(MONTH(F22)<MONTH(BLN),"1"&I22,VALUE) -> 14-101-001 | F22: 46062 | G22: INV-00114 | H22: Drop Of Cimaja | I22: 4-101-001 | J22: =IF(ISNA(VLOOKUP(I22,DAF_AKUN,2,FALSE)),"-",VLOOKUP(I22,DAF_AKUN,2,FALSE)) -> Pendapatan Usaha | M22: 1300000
A23: =IF(I23=VALUE,VALUE,COUNTIF($B$7:B23,B23))&I23&IF(F23<>VALUE,TEXT(F23,"mmmm"),VALUE) -> 44-101-001February | B23: =I23&IF(F23<>VALUE,TEXT(F23,"mmmm"),VALUE) -> 4-101-001February | C23: =COUNTIF($K$7:K23,K23)&K23 -> 0 | D23: =IF(MONTH(F23)<MONTH(BLN),"1"&I23,VALUE) -> 14-101-001 | F23: 46062 | G23: INV-00114 | H23: Room 3, Room Ibu, Surfing Board & Drop of Bandung | I23: 4-101-001 | J23: =IF(ISNA(VLOOKUP(I23,DAF_AKUN,2,FALSE)),"-",VLOOKUP(I23,DAF_AKUN,2,FALSE)) -> Pendapatan Usaha | M23: 4950000
A24: =IF(I24=VALUE,VALUE,COUNTIF($B$7:B24,B24))&I24&IF(F24<>VALUE,TEXT(F24,"mmmm"),VALUE) -> 54-101-001February | B24: =I24&IF(F24<>VALUE,TEXT(F24,"mmmm"),VALUE) -> 4-101-001February | C24: =COUNTIF($K$7:K24,K24)&K24 -> 0 | D24: =IF(MONTH(F24)<MONTH(BLN),"1"&I24,VALUE) -> 14-101-001 | F24: 46064 | G24: INV-00115 | H24: Room 4 | I24: 4-101-001 | J24: =IF(ISNA(VLOOKUP(I24,DAF_AKUN,2,FALSE)),"-",VLOOKUP(I24,DAF_AKUN,2,FALSE)) -> Pendapatan Usaha | M24: 500000
A25: =IF(I25=VALUE,VALUE,COUNTIF($B$7:B25,B25))&I25&IF(F25<>VALUE,TEXT(F25,"mmmm"),VALUE) -> 64-101-001February | B25: =I25&IF(F25<>VALUE,TEXT(F25,"mmmm"),VALUE) -> 4-101-001February | C25: =COUNTIF($K$7:K25,K25)&K25 -> 0 | D25: =IF(MONTH(F25)<MONTH(BLN),"1"&I25,VALUE) -> 14-101-001 | F25: 46068 | G25: INV-00117 | H25: Room 3 | I25: 4-101-001 | J25: =IF(ISNA(VLOOKUP(I25,DAF_AKUN,2,FALSE)),"-",VLOOKUP(I25,DAF_AKUN,2,FALSE)) -> Pendapatan Usaha | M25: 500000
A26: =IF(I26=VALUE,VALUE,COUNTIF($B$7:B26,B26))&I26&IF(F26<>VALUE,TEXT(F26,"mmmm"),VALUE) -> 74-101-001February | B26: =I26&IF(F26<>VALUE,TEXT(F26,"mmmm"),VALUE) -> 4-101-001February | C26: =COUNTIF($K$7:K26,K26)&K26 -> 0 | D26: =IF(MONTH(F26)<MONTH(BLN),"1"&I26,VALUE) -> 14-101-001 | F26: 46072 | G26: INV-00118 | H26: Surfing Board & Lesson | I26: 4-101-001 | J26: =IF(ISNA(VLOOKUP(I26,DAF_AKUN,2,FALSE)),"-",VLOOKUP(I26,DAF_AKUN,2,FALSE)) -> Pendapatan Usaha | M26: 3500000
A27: =IF(I27=VALUE,VALUE,COUNTIF($B$7:B27,B27))&I27&IF(F27<>VALUE,TEXT(F27,"mmmm"),VALUE) -> 11-102-001March | B27: =I27&IF(F27<>VALUE,TEXT(F27,"mmmm"),VALUE) -> 1-102-001March | C27: =COUNTIF($K$7:K27,K27)&K27 -> 0 | D27: =IF(MONTH(F27)<MONTH(BLN),"1"&I27,VALUE) -> 11-102-001 | F27: 46112 | H27: Sales Maret 2026 | I27: 1-102-001 | J27: =IF(ISNA(VLOOKUP(I27,DAF_AKUN,2,FALSE)),"-",VLOOKUP(I27,DAF_AKUN,2,FALSE)) -> Receivable - Trade | L27: =SUM(M28:M34) -> 5625000
A28: =IF(I28=VALUE,VALUE,COUNTIF($B$7:B28,B28))&I28&IF(F28<>VALUE,TEXT(F28,"mmmm"),VALUE) -> 14-101-001March | B28: =I28&IF(F28<>VALUE,TEXT(F28,"mmmm"),VALUE) -> 4-101-001March | C28: =COUNTIF($K$7:K28,K28)&K28 -> 0 | D28: =IF(MONTH(F28)<MONTH(BLN),"1"&I28,VALUE) -> 14-101-001 | F28: 46089 | G28: INV-00124 | H28: Room 3 | I28: 4-101-001 | J28: =IF(ISNA(VLOOKUP(I28,DAF_AKUN,2,FALSE)),"-",VLOOKUP(I28,DAF_AKUN,2,FALSE)) -> Pendapatan Usaha | M28: 1050000
A29: =IF(I29=VALUE,VALUE,COUNTIF($B$7:B29,B29))&I29&IF(F29<>VALUE,TEXT(F29,"mmmm"),VALUE) -> 24-101-001March | B29: =I29&IF(F29<>VALUE,TEXT(F29,"mmmm"),VALUE) -> 4-101-001March | C29: =COUNTIF($K$7:K29,K29)&K29 -> 0 | D29: =IF(MONTH(F29)<MONTH(BLN),"1"&I29,VALUE) -> 14-101-001 | F29: 46095 | G29: INV-00124 | H29: Room 2 | I29: 4-101-001 | J29: =IF(ISNA(VLOOKUP(I29,DAF_AKUN,2,FALSE)),"-",VLOOKUP(I29,DAF_AKUN,2,FALSE)) -> Pendapatan Usaha | M29: 275000
A30: =IF(I30=VALUE,VALUE,COUNTIF($B$7:B30,B30))&I30&IF(F30<>VALUE,TEXT(F30,"mmmm"),VALUE) -> 34-101-001March | B30: =I30&IF(F30<>VALUE,TEXT(F30,"mmmm"),VALUE) -> 4-101-001March | C30: =COUNTIF($K$7:K30,K30)&K30 -> 0 | D30: =IF(MONTH(F30)<MONTH(BLN),"1"&I30,VALUE) -> 14-101-001 | F30: 46101 | G30: INV-00130 | H30: Room 3 & 4 | I30: 4-101-001 | J30: =IF(ISNA(VLOOKUP(I30,DAF_AKUN,2,FALSE)),"-",VLOOKUP(I30,DAF_AKUN,2,FALSE)) -> Pendapatan Usaha | M30: 1575000
A31: =IF(I31=VALUE,VALUE,COUNTIF($B$7:B31,B31))&I31&IF(F31<>VALUE,TEXT(F31,"mmmm"),VALUE) -> 44-101-001March | B31: =I31&IF(F31<>VALUE,TEXT(F31,"mmmm"),VALUE) -> 4-101-001March | C31: =COUNTIF($K$7:K31,K31)&K31 -> 0 | D31: =IF(MONTH(F31)<MONTH(BLN),"1"&I31,VALUE) -> 14-101-001 | F31: 46101 | G31: INV-00130 | H31: Room 6 | I31: 4-101-001 | J31: =IF(ISNA(VLOOKUP(I31,DAF_AKUN,2,FALSE)),"-",VLOOKUP(I31,DAF_AKUN,2,FALSE)) -> Pendapatan Usaha | M31: 500000
A32: =IF(I32=VALUE,VALUE,COUNTIF($B$7:B32,B32))&I32&IF(F32<>VALUE,TEXT(F32,"mmmm"),VALUE) -> 54-101-001March | B32: =I32&IF(F32<>VALUE,TEXT(F32,"mmmm"),VALUE) -> 4-101-001March | C32: =COUNTIF($K$7:K32,K32)&K32 -> 0 | D32: =IF(MONTH(F32)<MONTH(BLN),"1"&I32,VALUE) -> 14-101-001 | F32: 46104 | G32: INV-00132 | H32: Room 5 | I32: 4-101-001 | J32: =IF(ISNA(VLOOKUP(I32,DAF_AKUN,2,FALSE)),"-",VLOOKUP(I32,DAF_AKUN,2,FALSE)) -> Pendapatan Usaha | M32: 275000
A33: =IF(I33=VALUE,VALUE,COUNTIF($B$7:B33,B33))&I33&IF(F33<>VALUE,TEXT(F33,"mmmm"),VALUE) -> 64-101-001March | B33: =I33&IF(F33<>VALUE,TEXT(F33,"mmmm"),VALUE) -> 4-101-001March | C33: =COUNTIF($K$7:K33,K33)&K33 -> 0 | D33: =IF(MONTH(F33)<MONTH(BLN),"1"&I33,VALUE) -> 14-101-001 | F33: 46104 | G33: INV-00131 | H33: Room 1, 4 & 5 | I33: 4-101-001 | J33: =IF(ISNA(VLOOKUP(I33,DAF_AKUN,2,FALSE)),"-",VLOOKUP(I33,DAF_AKUN,2,FALSE)) -> Pendapatan Usaha | M33: 1350000
A34: =IF(I34=VALUE,VALUE,COUNTIF($B$7:B34,B34))&I34&IF(F34<>VALUE,TEXT(F34,"mmmm"),VALUE) -> 74-101-001March | B34: =I34&IF(F34<>VALUE,TEXT(F34,"mmmm"),VALUE) -> 4-101-001March | C34: =COUNTIF($K$7:K34,K34)&K34 -> 0 | D34: =IF(MONTH(F34)<MONTH(BLN),"1"&I34,VALUE) -> 14-101-001 | F34: 46109 | G34: INV-00135 | H34: Room 3 | I34: 4-101-001 | J34: =IF(ISNA(VLOOKUP(I34,DAF_AKUN,2,FALSE)),"-",VLOOKUP(I34,DAF_AKUN,2,FALSE)) -> Pendapatan Usaha | M34: 600000
A35: =IF(I35=VALUE,VALUE,COUNTIF($B$7:B35,B35))&I35&IF(F35<>VALUE,TEXT(F35,"mmmm"),VALUE) -> 11-102-001April | B35: =I35&IF(F35<>VALUE,TEXT(F35,"mmmm"),VALUE) -> 1-102-001April | C35: =COUNTIF($K$7:K35,K35)&K35 -> 0 | D35: =IF(MONTH(F35)<MONTH(BLN),"1"&I35,VALUE) -> 11-102-001 | F35: 46113 | G35: INV-00135 | H35: Room 3 | I35: 1-102-001 | J35: =IF(ISNA(VLOOKUP(I35,DAF_AKUN,2,FALSE)),"-",VLOOKUP(I35,DAF_AKUN,2,FALSE)) -> Receivable - Trade | L35: 3850000
A36: =IF(I36=VALUE,VALUE,COUNTIF($B$7:B36,B36))&I36&IF(F36<>VALUE,TEXT(F36,"mmmm"),VALUE) -> 14-101-001April | B36: =I36&IF(F36<>VALUE,TEXT(F36,"mmmm"),VALUE) -> 4-101-001April | C36: =COUNTIF($K$7:K36,K36)&K36 -> 0 | D36: =IF(MONTH(F36)<MONTH(BLN),"1"&I36,VALUE) -> 14-101-001 | F36: 46113 | G36: INV-00135 | H36: Room 3 | I36: 4-101-001 | J36: =IF(ISNA(VLOOKUP(I36,DAF_AKUN,2,FALSE)),"-",VLOOKUP(I36,DAF_AKUN,2,FALSE)) -> Pendapatan Usaha | M36: 3850000
A37: =IF(I37=VALUE,VALUE,COUNTIF($B$7:B37,B37))&I37&IF(F37<>VALUE,TEXT(F37,"mmmm"),VALUE) -> 11-102-001June | B37: =I37&IF(F37<>VALUE,TEXT(F37,"mmmm"),VALUE) -> 1-102-001June | C37: =COUNTIF($K$7:K37,K37)&K37 -> 0 | D37: =IF(MONTH(F37)<MONTH(BLN),"1"&I37,VALUE) -> 11-102-001 | F37: 46203 | H37: Sales Juni 2026 | I37: 1-102-001 | J37: =IF(ISNA(VLOOKUP(I37,DAF_AKUN,2,FALSE)),"-",VLOOKUP(I37,DAF_AKUN,2,FALSE)) -> Receivable - Trade | L37: =SUM(M38:M48) -> 23140000
A38: =IF(I38=VALUE,VALUE,COUNTIF($B$7:B38,B38))&I38&IF(F38<>VALUE,TEXT(F38,"mmmm"),VALUE) -> 14-101-001June | B38: =I38&IF(F38<>VALUE,TEXT(F38,"mmmm"),VALUE) -> 4-101-001June | C38: =COUNTIF($K$7:K38,K38)&K38 -> 0 | D38: =IF(MONTH(F38)<MONTH(BLN),"1"&I38,VALUE) -> 14-101-001 | F38: 46186 | G38: INV-00184 | H38: Room 1 | I38: 4-101-001 | J38: =IF(ISNA(VLOOKUP(I38,DAF_AKUN,2,FALSE)),"-",VLOOKUP(I38,DAF_AKUN,2,FALSE)) -> Pendapatan Usaha | M38: 2250000
A39: =IF(I39=VALUE,VALUE,COUNTIF($B$7:B39,B39))&I39&IF(F39<>VALUE,TEXT(F39,"mmmm"),VALUE) -> 24-101-001June | B39: =I39&IF(F39<>VALUE,TEXT(F39,"mmmm"),VALUE) -> 4-101-001June | C39: =COUNTIF($K$7:K39,K39)&K39 -> 0 | D39: =IF(MONTH(F39)<MONTH(BLN),"1"&I39,VALUE) -> 14-101-001 | F39: 46187 | G39: INV-00186 | H39: Room 2 | I39: 4-101-001 | J39: =IF(ISNA(VLOOKUP(I39,DAF_AKUN,2,FALSE)),"-",VLOOKUP(I39,DAF_AKUN,2,FALSE)) -> Pendapatan Usaha | M39: 1100000
A40: =IF(I40=VALUE,VALUE,COUNTIF($B$7:B40,B40))&I40&IF(F40<>VALUE,TEXT(F40,"mmmm"),VALUE) -> 34-101-001June | B40: =I40&IF(F40<>VALUE,TEXT(F40,"mmmm"),VALUE) -> 4-101-001June | C40: =COUNTIF($K$7:K40,K40)&K40 -> 0 | D40: =IF(MONTH(F40)<MONTH(BLN),"1"&I40,VALUE) -> 14-101-001 | F40: 46187 | G40: INV-00185 | H40: Room 3 | I40: 4-101-001 | J40: =IF(ISNA(VLOOKUP(I40,DAF_AKUN,2,FALSE)),"-",VLOOKUP(I40,DAF_AKUN,2,FALSE)) -> Pendapatan Usaha | M40: 700000
...

Sheet Atur Laporan
C7: ="Tahun : "&THN -> Tahun : 2026
C9: Bulan | D9: 183

Sheet Buku Besar
A1: =NAMA -> ARYA USAHA TIRTA, CV
A2: BUKU BESAR
A3: ="Bulan : "&TEXT(TEXT(BLN,"mmmm"),"mmmm")&" "&THN -> Bulan : July 2026
A5: Kode Akun | C5: 1-120-005 | F5: Pos Saldo : | G5: =VLOOKUP(C5,DAF_AKUN,3,FALSE) -> Db
A6: Nama Akun | C6: =VLOOKUP(C5,DAF_AKUN,2,FALSE) -> Electronics & IT Equipment | F6: Saldo Awal : | G6: =IF(ISERROR=TRUE,IF(AND(ISERROR=TRUE,VLOOKUP(C5,DAF_AKUN,3,FALSE)="Db"),SUMIF(Akun!A:A,C5,Akun!F:F)+SUMIF(Jurnal!D:D,"1"&C5,Jurnal!L:L)-SUMIF(Jurnal!D:D,"1"&C5,Jurnal!M:M),SUMIF(Akun!A:A,C5,Akun!G:G)-SUMIF(Jurnal!D:D,"1"&C5,Jurnal!L:L)+SUMIF(Jurnal!D:D,"1"&C5,Jurnal!M:M)),VALUE) -> 9550321
A8: No | B8: Tanggal | C8: Bukti | D8: Keterangan | E8: Debet | F8: Kredit | G8: Saldo
A10: =A9+1 -> 1 | B10: =IF(OR(ISERROR=FALSE,ISERROR(VLOOKUP(A10&C$5&TEXT(BLN,"mmmm"),JU_AKUN,6,FALSE))=TRUE),TEXT,VLOOKUP(A10&C$5&TEXT(BLN,"mmmm"),JU_AKUN,6,FALSE)) -> - | C10: =IF(OR(ISERROR=FALSE,ISERROR(VLOOKUP(A10&C$5&TEXT(BLN,"mmmm"),JU_AKUN,7,FALSE))=TRUE),TEXT,VLOOKUP(A10&C$5&TEXT(BLN,"mmmm"),JU_AKUN,7,FALSE)) -> - | D10: =IF(OR(ISERROR=FALSE,ISERROR(VLOOKUP(A10&C$5&TEXT(BLN,"mmmm"),JU_AKUN,8,FALSE))=TRUE),TEXT,VLOOKUP(A10&C$5&TEXT(BLN,"mmmm"),JU_AKUN,8,FALSE)) -> - | E10: =IF(OR(ISERROR=FALSE,ISERROR(VLOOKUP(A10&C$5&TEXT(BLN,"mmmm"),JU_AKUN,12,FALSE))=TRUE),TEXT,VLOOKUP(A10&C$5&TEXT(BLN,"mmmm"),JU_AKUN,12,FALSE)) -> - | F10: =IF(OR(ISERROR=FALSE,ISERROR(VLOOKUP(A10&C$5&TEXT(BLN,"mmmm"),JU_AKUN,13,FALSE))=TRUE),TEXT,VLOOKUP(A10&C$5&TEXT(BLN,"mmmm"),JU_AKUN,13,FALSE)) -> - | G10: =IF(AND(E10=TEXT,F10=TEXT),VALUE,IF($G$5="Db",$G$6+SUM($E$10:E10)-SUM($F$10:F10),$G$6-SUM($E$10:E10)+SUM($F$10:F10))) -> 0
A11: =A10+1 -> 2 | B11: =IF(OR(ISERROR=FALSE,ISERROR(VLOOKUP(A11&C$5&TEXT(BLN,"mmmm"),JU_AKUN,6,FALSE))=TRUE),TEXT,VLOOKUP(A11&C$5&TEXT(BLN,"mmmm"),JU_AKUN,6,FALSE)) -> - | C11: =IF(OR(ISERROR=FALSE,ISERROR(VLOOKUP(A11&C$5&TEXT(BLN,"mmmm"),JU_AKUN,7,FALSE))=TRUE),TEXT,VLOOKUP(A11&C$5&TEXT(BLN,"mmmm"),JU_AKUN,7,FALSE)) -> - | D11: =IF(OR(ISERROR=FALSE,ISERROR(VLOOKUP(A11&C$5&TEXT(BLN,"mmmm"),JU_AKUN,8,FALSE))=TRUE),TEXT,VLOOKUP(A11&C$5&TEXT(BLN,"mmmm"),JU_AKUN,8,FALSE)) -> - | E11: =IF(OR(ISERROR=FALSE,ISERROR(VLOOKUP(A11&C$5&TEXT(BLN,"mmmm"),JU_AKUN,12,FALSE))=TRUE),TEXT,VLOOKUP(A11&C$5&TEXT(BLN,"mmmm"),JU_AKUN,12,FALSE)) -> - | F11: =IF(OR(ISERROR=FALSE,ISERROR(VLOOKUP(A11&C$5&TEXT(BLN,"mmmm"),JU_AKUN,13,FALSE))=TRUE),TEXT,VLOOKUP(A11&C$5&TEXT(BLN,"mmmm"),JU_AKUN,13,FALSE)) -> - | G11: =IF(AND(E11=TEXT,F11=TEXT),VALUE,IF($G$5="Db",$G$6+SUM($E$10:E11)-SUM($F$10:F11),$G$6-SUM($E$10:E11)+SUM($F$10:F11))) -> 0
A12: =A11+1 -> 3 | B12: =IF(OR(ISERROR=FALSE,ISERROR(VLOOKUP(A12&C$5&TEXT(BLN,"mmmm"),JU_AKUN,6,FALSE))=TRUE),TEXT,VLOOKUP(A12&C$5&TEXT(BLN,"mmmm"),JU_AKUN,6,FALSE)) -> - | C12: =IF(OR(ISERROR=FALSE,ISERROR(VLOOKUP(A12&C$5&TEXT(BLN,"mmmm"),JU_AKUN,7,FALSE))=TRUE),TEXT,VLOOKUP(A12&C$5&TEXT(BLN,"mmmm"),JU_AKUN,7,FALSE)) -> - | D12: =IF(OR(ISERROR=FALSE,ISERROR(VLOOKUP(A12&C$5&TEXT(BLN,"mmmm"),JU_AKUN,8,FALSE))=TRUE),TEXT,VLOOKUP(A12&C$5&TEXT(BLN,"mmmm"),JU_AKUN,8,FALSE)) -> - | E12: =IF(OR(ISERROR=FALSE,ISERROR(VLOOKUP(A12&C$5&TEXT(BLN,"mmmm"),JU_AKUN,12,FALSE))=TRUE),TEXT,VLOOKUP(A12&C$5&TEXT(BLN,"mmmm"),JU_AKUN,12,FALSE)) -> - | F12: =IF(OR(ISERROR=FALSE,ISERROR(VLOOKUP(A12&C$5&TEXT(BLN,"mmmm"),JU_AKUN,13,FALSE))=TRUE),TEXT,VLOOKUP(A12&C$5&TEXT(BLN,"mmmm"),JU_AKUN,13,FALSE)) -> - | G12: =IF(AND(E12=TEXT,F12=TEXT),VALUE,IF($G$5="Db",$G$6+SUM($E$10:E12)-SUM($F$10:F12),$G$6-SUM($E$10:E12)+SUM($F$10:F12))) -> 0
A13: =A12+1 -> 4 | B13: =IF(OR(ISERROR=FALSE,ISERROR(VLOOKUP(A13&C$5&TEXT(BLN,"mmmm"),JU_AKUN,6,FALSE))=TRUE),TEXT,VLOOKUP(A13&C$5&TEXT(BLN,"mmmm"),JU_AKUN,6,FALSE)) -> - | C13: =IF(OR(ISERROR=FALSE,ISERROR(VLOOKUP(A13&C$5&TEXT(BLN,"mmmm"),JU_AKUN,7,FALSE))=TRUE),TEXT,VLOOKUP(A13&C$5&TEXT(BLN,"mmmm"),JU_AKUN,7,FALSE)) -> - | D13: =IF(OR(ISERROR=FALSE,ISERROR(VLOOKUP(A13&C$5&TEXT(BLN,"mmmm"),JU_AKUN,8,FALSE))=TRUE),TEXT,VLOOKUP(A13&C$5&TEXT(BLN,"mmmm"),JU_AKUN,8,FALSE)) -> - | E13: =IF(OR(ISERROR=FALSE,ISERROR(VLOOKUP(A13&C$5&TEXT(BLN,"mmmm"),JU_AKUN,12,FALSE))=TRUE),TEXT,VLOOKUP(A13&C$5&TEXT(BLN,"mmmm"),JU_AKUN,12,FALSE)) -> - | F13: =IF(OR(ISERROR=FALSE,ISERROR(VLOOKUP(A13&C$5&TEXT(BLN,"mmmm"),JU_AKUN,13,FALSE))=TRUE),TEXT,VLOOKUP(A13&C$5&TEXT(BLN,"mmmm"),JU_AKUN,13,FALSE)) -> - | G13: =IF(AND(E13=TEXT,F13=TEXT),VALUE,IF($G$5="Db",$G$6+SUM($E$10:E13)-SUM($F$10:F13),$G$6-SUM($E$10:E13)+SUM($F$10:F13))) -> 0
A14: =A13+1 -> 5 | B14: =IF(OR(ISERROR=FALSE,ISERROR(VLOOKUP(A14&C$5&TEXT(BLN,"mmmm"),JU_AKUN,6,FALSE))=TRUE),TEXT,VLOOKUP(A14&C$5&TEXT(BLN,"mmmm"),JU_AKUN,6,FALSE)) -> - | C14: =IF(OR(ISERROR=FALSE,ISERROR(VLOOKUP(A14&C$5&TEXT(BLN,"mmmm"),JU_AKUN,7,FALSE))=TRUE),TEXT,VLOOKUP(A14&C$5&TEXT(BLN,"mmmm"),JU_AKUN,7,FALSE)) -> - | D14: =IF(OR(ISERROR=FALSE,ISERROR(VLOOKUP(A14&C$5&TEXT(BLN,"mmmm"),JU_AKUN,8,FALSE))=TRUE),TEXT,VLOOKUP(A14&C$5&TEXT(BLN,"mmmm"),JU_AKUN,8,FALSE)) -> - | E14: =IF(OR(ISERROR=FALSE,ISERROR(VLOOKUP(A14&C$5&TEXT(BLN,"mmmm"),JU_AKUN,12,FALSE))=TRUE),TEXT,VLOOKUP(A14&C$5&TEXT(BLN,"mmmm"),JU_AKUN,12,FALSE)) -> - | F14: =IF(OR(ISERROR=FALSE,ISERROR(VLOOKUP(A14&C$5&TEXT(BLN,"mmmm"),JU_AKUN,13,FALSE))=TRUE),TEXT,VLOOKUP(A14&C$5&TEXT(BLN,"mmmm"),JU_AKUN,13,FALSE)) -> - | G14: =IF(AND(E14=TEXT,F14=TEXT),VALUE,IF($G$5="Db",$G$6+SUM($E$10:E14)-SUM($F$10:F14),$G$6-SUM($E$10:E14)+SUM($F$10:F14))) -> 0
A15: =A14+1 -> 6 | B15: =IF(OR(ISERROR=FALSE,ISERROR(VLOOKUP(A15&C$5&TEXT(BLN,"mmmm"),JU_AKUN,6,FALSE))=TRUE),TEXT,VLOOKUP(A15&C$5&TEXT(BLN,"mmmm"),JU_AKUN,6,FALSE)) -> - | C15: =IF(OR(ISERROR=FALSE,ISERROR(VLOOKUP(A15&C$5&TEXT(BLN,"mmmm"),JU_AKUN,7,FALSE))=TRUE),TEXT,VLOOKUP(A15&C$5&TEXT(BLN,"mmmm"),JU_AKUN,7,FALSE)) -> - | D15: =IF(OR(ISERROR=FALSE,ISERROR(VLOOKUP(A15&C$5&TEXT(BLN,"mmmm"),JU_AKUN,8,FALSE))=TRUE),TEXT,VLOOKUP(A15&C$5&TEXT(BLN,"mmmm"),JU_AKUN,8,FALSE)) -> - | E15: =IF(OR(ISERROR=FALSE,ISERROR(VLOOKUP(A15&C$5&TEXT(BLN,"mmmm"),JU_AKUN,12,FALSE))=TRUE),TEXT,VLOOKUP(A15&C$5&TEXT(BLN,"mmmm"),JU_AKUN,12,FALSE)) -> - | F15: =IF(OR(ISERROR=FALSE,ISERROR(VLOOKUP(A15&C$5&TEXT(BLN,"mmmm"),JU_AKUN,13,FALSE))=TRUE),TEXT,VLOOKUP(A15&C$5&TEXT(BLN,"mmmm"),JU_AKUN,13,FALSE)) -> - | G15: =IF(AND(E15=TEXT,F15=TEXT),VALUE,IF($G$5="Db",$G$6+SUM($E$10:E15)-SUM($F$10:F15),$G$6-SUM($E$10:E15)+SUM($F$10:F15))) -> 0
A16: =A15+1 -> 7 | B16: =IF(OR(ISERROR=FALSE,ISERROR(VLOOKUP(A16&C$5&TEXT(BLN,"mmmm"),JU_AKUN,6,FALSE))=TRUE),TEXT,VLOOKUP(A16&C$5&TEXT(BLN,"mmmm"),JU_AKUN,6,FALSE)) -> - | C16: =IF(OR(ISERROR=FALSE,ISERROR(VLOOKUP(A16&C$5&TEXT(BLN,"mmmm"),JU_AKUN,7,FALSE))=TRUE),TEXT,VLOOKUP(A16&C$5&TEXT(BLN,"mmmm"),JU_AKUN,7,FALSE)) -> - | D16: =IF(OR(ISERROR=FALSE,ISERROR(VLOOKUP(A16&C$5&TEXT(BLN,"mmmm"),JU_AKUN,8,FALSE))=TRUE),TEXT,VLOOKUP(A16&C$5&TEXT(BLN,"mmmm"),JU_AKUN,8,FALSE)) -> - | E16: =IF(OR(ISERROR=FALSE,ISERROR(VLOOKUP(A16&C$5&TEXT(BLN,"mmmm"),JU_AKUN,12,FALSE))=TRUE),TEXT,VLOOKUP(A16&C$5&TEXT(BLN,"mmmm"),JU_AKUN,12,FALSE)) -> - | F16: =IF(OR(ISERROR=FALSE,ISERROR(VLOOKUP(A16&C$5&TEXT(BLN,"mmmm"),JU_AKUN,13,FALSE))=TRUE),TEXT,VLOOKUP(A16&C$5&TEXT(BLN,"mmmm"),JU_AKUN,13,FALSE)) -> - | G16: =IF(AND(E16=TEXT,F16=TEXT),VALUE,IF($G$5="Db",$G$6+SUM($E$10:E16)-SUM($F$10:F16),$G$6-SUM($E$10:E16)+SUM($F$10:F16))) -> 0
A17: =A16+1 -> 8 | B17: =IF(OR(ISERROR=FALSE,ISERROR(VLOOKUP(A17&C$5&TEXT(BLN,"mmmm"),JU_AKUN,6,FALSE))=TRUE),TEXT,VLOOKUP(A17&C$5&TEXT(BLN,"mmmm"),JU_AKUN,6,FALSE)) -> - | C17: =IF(OR(ISERROR=FALSE,ISERROR(VLOOKUP(A17&C$5&TEXT(BLN,"mmmm"),JU_AKUN,7,FALSE))=TRUE),TEXT,VLOOKUP(A17&C$5&TEXT(BLN,"mmmm"),JU_AKUN,7,FALSE)) -> - | D17: =IF(OR(ISERROR=FALSE,ISERROR(VLOOKUP(A17&C$5&TEXT(BLN,"mmmm"),JU_AKUN,8,FALSE))=TRUE),TEXT,VLOOKUP(A17&C$5&TEXT(BLN,"mmmm"),JU_AKUN,8,FALSE)) -> - | E17: =IF(OR(ISERROR=FALSE,ISERROR(VLOOKUP(A17&C$5&TEXT(BLN,"mmmm"),JU_AKUN,12,FALSE))=TRUE),TEXT,VLOOKUP(A17&C$5&TEXT(BLN,"mmmm"),JU_AKUN,12,FALSE)) -> - | F17: =IF(OR(ISERROR=FALSE,ISERROR(VLOOKUP(A17&C$5&TEXT(BLN,"mmmm"),JU_AKUN,13,FALSE))=TRUE),TEXT,VLOOKUP(A17&C$5&TEXT(BLN,"mmmm"),JU_AKUN,13,FALSE)) -> - | G17: =IF(AND(E17=TEXT,F17=TEXT),VALUE,IF($G$5="Db",$G$6+SUM($E$10:E17)-SUM($F$10:F17),$G$6-SUM($E$10:E17)+SUM($F$10:F17))) -> 0
A18: =A17+1 -> 9 | B18: =IF(OR(ISERROR=FALSE,ISERROR(VLOOKUP(A18&C$5&TEXT(BLN,"mmmm"),JU_AKUN,6,FALSE))=TRUE),TEXT,VLOOKUP(A18&C$5&TEXT(BLN,"mmmm"),JU_AKUN,6,FALSE)) -> - | C18: =IF(OR(ISERROR=FALSE,ISERROR(VLOOKUP(A18&C$5&TEXT(BLN,"mmmm"),JU_AKUN,7,FALSE))=TRUE),TEXT,VLOOKUP(A18&C$5&TEXT(BLN,"mmmm"),JU_AKUN,7,FALSE)) -> - | D18: =IF(OR(ISERROR=FALSE,ISERROR(VLOOKUP(A18&C$5&TEXT(BLN,"mmmm"),JU_AKUN,8,FALSE))=TRUE),TEXT,VLOOKUP(A18&C$5&TEXT(BLN,"mmmm"),JU_AKUN,8,FALSE)) -> - | E18: =IF(OR(ISERROR=FALSE,ISERROR(VLOOKUP(A18&C$5&TEXT(BLN,"mmmm"),JU_AKUN,12,FALSE))=TRUE),TEXT,VLOOKUP(A18&C$5&TEXT(BLN,"mmmm"),JU_AKUN,12,FALSE)) -> - | F18: =IF(OR(ISERROR=FALSE,ISERROR(VLOOKUP(A18&C$5&TEXT(BLN,"mmmm"),JU_AKUN,13,FALSE))=TRUE),TEXT,VLOOKUP(A18&C$5&TEXT(BLN,"mmmm"),JU_AKUN,13,FALSE)) -> - | G18: =IF(AND(E18=TEXT,F18=TEXT),VALUE,IF($G$5="Db",$G$6+SUM($E$10:E18)-SUM($F$10:F18),$G$6-SUM($E$10:E18)+SUM($F$10:F18))) -> 0
A19: =A18+1 -> 10 | B19: =IF(OR(ISERROR=FALSE,ISERROR(VLOOKUP(A19&C$5&TEXT(BLN,"mmmm"),JU_AKUN,6,FALSE))=TRUE),TEXT,VLOOKUP(A19&C$5&TEXT(BLN,"mmmm"),JU_AKUN,6,FALSE)) -> - | C19: =IF(OR(ISERROR=FALSE,ISERROR(VLOOKUP(A19&C$5&TEXT(BLN,"mmmm"),JU_AKUN,7,FALSE))=TRUE),TEXT,VLOOKUP(A19&C$5&TEXT(BLN,"mmmm"),JU_AKUN,7,FALSE)) -> - | D19: =IF(OR(ISERROR=FALSE,ISERROR(VLOOKUP(A19&C$5&TEXT(BLN,"mmmm"),JU_AKUN,8,FALSE))=TRUE),TEXT,VLOOKUP(A19&C$5&TEXT(BLN,"mmmm"),JU_AKUN,8,FALSE)) -> - | E19: =IF(OR(ISERROR=FALSE,ISERROR(VLOOKUP(A19&C$5&TEXT(BLN,"mmmm"),JU_AKUN,12,FALSE))=TRUE),TEXT,VLOOKUP(A19&C$5&TEXT(BLN,"mmmm"),JU_AKUN,12,FALSE)) -> - | F19: =IF(OR(ISERROR=FALSE,ISERROR(VLOOKUP(A19&C$5&TEXT(BLN,"mmmm"),JU_AKUN,13,FALSE))=TRUE),TEXT,VLOOKUP(A19&C$5&TEXT(BLN,"mmmm"),JU_AKUN,13,FALSE)) -> - | G19: =IF(AND(E19=TEXT,F19=TEXT),VALUE,IF($G$5="Db",$G$6+SUM($E$10:E19)-SUM($F$10:F19),$G$6-SUM($E$10:E19)+SUM($F$10:F19))) -> 0
A20: =A19+1 -> 11 | B20: =IF(OR(ISERROR=FALSE,ISERROR(VLOOKUP(A20&C$5&TEXT(BLN,"mmmm"),JU_AKUN,6,FALSE))=TRUE),TEXT,VLOOKUP(A20&C$5&TEXT(BLN,"mmmm"),JU_AKUN,6,FALSE)) -> - | C20: =IF(OR(ISERROR=FALSE,ISERROR(VLOOKUP(A20&C$5&TEXT(BLN,"mmmm"),JU_AKUN,7,FALSE))=TRUE),TEXT,VLOOKUP(A20&C$5&TEXT(BLN,"mmmm"),JU_AKUN,7,FALSE)) -> - | D20: =IF(OR(ISERROR=FALSE,ISERROR(VLOOKUP(A20&C$5&TEXT(BLN,"mmmm"),JU_AKUN,8,FALSE))=TRUE),TEXT,VLOOKUP(A20&C$5&TEXT(BLN,"mmmm"),JU_AKUN,8,FALSE)) -> - | E20: =IF(OR(ISERROR=FALSE,ISERROR(VLOOKUP(A20&C$5&TEXT(BLN,"mmmm"),JU_AKUN,12,FALSE))=TRUE),TEXT,VLOOKUP(A20&C$5&TEXT(BLN,"mmmm"),JU_AKUN,12,FALSE)) -> - | F20: =IF(OR(ISERROR=FALSE,ISERROR(VLOOKUP(A20&C$5&TEXT(BLN,"mmmm"),JU_AKUN,13,FALSE))=TRUE),TEXT,VLOOKUP(A20&C$5&TEXT(BLN,"mmmm"),JU_AKUN,13,FALSE)) -> - | G20: =IF(AND(E20=TEXT,F20=TEXT),VALUE,IF($G$5="Db",$G$6+SUM($E$10:E20)-SUM($F$10:F20),$G$6-SUM($E$10:E20)+SUM($F$10:F20))) -> 0
A21: =A20+1 -> 12 | B21: =IF(OR(ISERROR=FALSE,ISERROR(VLOOKUP(A21&C$5&TEXT(BLN,"mmmm"),JU_AKUN,6,FALSE))=TRUE),TEXT,VLOOKUP(A21&C$5&TEXT(BLN,"mmmm"),JU_AKUN,6,FALSE)) -> - | C21: =IF(OR(ISERROR=FALSE,ISERROR(VLOOKUP(A21&C$5&TEXT(BLN,"mmmm"),JU_AKUN,7,FALSE))=TRUE),TEXT,VLOOKUP(A21&C$5&TEXT(BLN,"mmmm"),JU_AKUN,7,FALSE)) -> - | D21: =IF(OR(ISERROR=FALSE,ISERROR(VLOOKUP(A21&C$5&TEXT(BLN,"mmmm"),JU_AKUN,8,FALSE))=TRUE),TEXT,VLOOKUP(A21&C$5&TEXT(BLN,"mmmm"),JU_AKUN,8,FALSE)) -> - | E21: =IF(OR(ISERROR=FALSE,ISERROR(VLOOKUP(A21&C$5&TEXT(BLN,"mmmm"),JU_AKUN,12,FALSE))=TRUE),TEXT,VLOOKUP(A21&C$5&TEXT(BLN,"mmmm"),JU_AKUN,12,FALSE)) -> - | F21: =IF(OR(ISERROR=FALSE,ISERROR(VLOOKUP(A21&C$5&TEXT(BLN,"mmmm"),JU_AKUN,13,FALSE))=TRUE),TEXT,VLOOKUP(A21&C$5&TEXT(BLN,"mmmm"),JU_AKUN,13,FALSE)) -> - | G21: =IF(AND(E21=TEXT,F21=TEXT),VALUE,IF($G$5="Db",$G$6+SUM($E$10:E21)-SUM($F$10:F21),$G$6-SUM($E$10:E21)+SUM($F$10:F21))) -> 0
... A108: =A107+1 -> 99 | B108: =IF(OR(ISERROR=FALSE,ISERROR(VLOOKUP(A108&C$5&TEXT(BLN,"mmmm"),JU_AKUN,6,FALSE))=TRUE),TEXT,VLOOKUP(A108&C$5&TEXT(BLN,"mmmm"),JU_AKUN,6,FALSE)) -> - | C108: =IF(OR(ISERROR=FALSE,ISERROR(VLOOKUP(A108&C$5&TEXT(BLN,"mmmm"),JU_AKUN,7,FALSE))=TRUE),TEXT,VLOOKUP(A108&C$5&TEXT(BLN,"mmmm"),JU_AKUN,7,FALSE)) -> - | D108: =IF(OR(ISERROR=FALSE,ISERROR(VLOOKUP(A108&C$5&TEXT(BLN,"mmmm"),JU_AKUN,8,FALSE))=TRUE),TEXT,VLOOKUP(A108&C$5&TEXT(BLN,"mmmm"),JU_AKUN,8,FALSE)) -> - | E108: =IF(OR(ISERROR=FALSE,ISERROR(VLOOKUP(A108&C$5&TEXT(BLN,"mmmm"),JU_AKUN,12,FALSE))=TRUE),TEXT,VLOOKUP(A108&C$5&TEXT(BLN,"mmmm"),JU_AKUN,12,FALSE)) -> - | F108: =IF(OR(ISERROR=FALSE,ISERROR(VLOOKUP(A108&C$5&TEXT(BLN,"mmmm"),JU_AKUN,13,FALSE))=TRUE),TEXT,VLOOKUP(A108&C$5&TEXT(BLN,"mmmm"),JU_AKUN,13,FALSE)) -> - | G108: =IF(AND(E108=TEXT,F108=TEXT),VALUE,IF($G$5="Db",$G$6+SUM($E$10:E108)-SUM($F$10:F108),$G$6-SUM($E$10:E108)+SUM($F$10:F108))) -> 0

Sheet Neraca Lajur
A1: =NAMA -> ARYA USAHA TIRTA, CV
A2: NERACA LAJUR
A3: ="S/D Bulan : "&TEXT(BLN,"mmmm")&" "&THN -> S/D Bulan : July 2026
A5: Kode | B5: Nama Akun | C5: Pos | D5: Neraca Saldo | F5: Pos | G5: Laba Rugi | I5: Neraca
A6: Akun | C6: Saldo | D6: Debet | E6: Kredit | F6: Laporan | G6: Debet | H6: Kredit | I6: Debet | J6: Kredit
A7: 100000000 | B7: =VLOOKUP(A7,DAF_AKUN,2,FALSE) -> AKTIVA | C7: =VLOOKUP(A7,DAF_AKUN,3,FALSE) -> 0 | D7: =IF(AND(ISERROR=TRUE,C7="Db"),SUMIF(AKUN1,A7,AKUN2)+SUMIF(JURN2,"1"&A7,JURN3)-SUMIF(JURN2,"1"&A7,JURN4)+SUMIF(JURN1,A7&TEXT(BLN,"mmmm"),JURN3)-SUMIF(JURN1,A7&TEXT(BLN,"mmmm"),JURN4),VALUE) -> 0 | E7: =IF(AND(ISERROR=TRUE,C7="Kr"),SUMIF(AKUN1,A7,AKUN3)-SUMIF(JURN2,"1"&A7,JURN3)+SUMIF(JURN2,"1"&A7,JURN4)+SUMIF(JURN1,A7&TEXT(BLN,"mmmm"),JURN4)-SUMIF(JURN1,A7&TEXT(BLN,"mmmm"),JURN3),VALUE) -> 0 | F7: =VLOOKUP(A7,DAF_AKUN,4,FALSE) -> 0 | G7: =IF(D7=TEXT,VALUE,IF(F7="LR",D7,0)) -> 0 | H7: =IF(E7=TEXT,VALUE,IF(F7="LR",E7,0)) -> 0 | I7: =IF(D7=TEXT,VALUE,IF(F7="NRC",D7,0)) -> 0 | J7: =IF(E7=TEXT,VALUE,IF(F7="NRC",E7,0)) -> 0
A8: 1-101-000 | B8: =VLOOKUP(A8,DAF_AKUN,2,FALSE) -> Kas dan Bank | C8: =VLOOKUP(A8,DAF_AKUN,3,FALSE) -> Db | D8: =IF(AND(ISERROR=TRUE,C8="Db"),SUMIF(AKUN1,A8,AKUN2)+SUMIF(JURN2,"1"&A8,JURN3)-SUMIF(JURN2,"1"&A8,JURN4)+SUMIF(JURN1,A8&TEXT(BLN,"mmmm"),JURN3)-SUMIF(JURN1,A8&TEXT(BLN,"mmmm"),JURN4),VALUE) -> 0 | E8: =IF(AND(ISERROR=TRUE,C8="Kr"),SUMIF(AKUN1,A8,AKUN3)-SUMIF(JURN2,"1"&A8,JURN3)+SUMIF(JURN2,"1"&A8,JURN4)+SUMIF(JURN1,A8&TEXT(BLN,"mmmm"),JURN4)-SUMIF(JURN1,A8&TEXT(BLN,"mmmm"),JURN3),VALUE) -> 0 | F8: =VLOOKUP(A8,DAF_AKUN,4,FALSE) -> NRC | G8: =IF(D8=TEXT,VALUE,IF(F8="LR",D8,0)) -> 0 | H8: =IF(E8=TEXT,VALUE,IF(F8="LR",E8,0)) -> 0 | I8: =IF(D8=TEXT,VALUE,IF(F8="NRC",D8,0)) -> 0 | J8: =IF(E8=TEXT,VALUE,IF(F8="NRC",E8,0)) -> 0
A9: 1-101-001 | B9: =VLOOKUP(A9,DAF_AKUN,2,FALSE) -> Petty Cash | C9: =VLOOKUP(A9,DAF_AKUN,3,FALSE) -> Db | D9: =IF(AND(ISERROR=TRUE,C9="Db"),SUMIF(AKUN1,A9,AKUN2)+SUMIF(JURN2,"1"&A9,JURN3)-SUMIF(JURN2,"1"&A9,JURN4)+SUMIF(JURN1,A9&TEXT(BLN,"mmmm"),JURN3)-SUMIF(JURN1,A9&TEXT(BLN,"mmmm"),JURN4),VALUE) -> 0 | E9: =IF(AND(ISERROR=TRUE,C9="Kr"),SUMIF(AKUN1,A9,AKUN3)-SUMIF(JURN2,"1"&A9,JURN3)+SUMIF(JURN2,"1"&A9,JURN4)+SUMIF(JURN1,A9&TEXT(BLN,"mmmm"),JURN4)-SUMIF(JURN1,A9&TEXT(BLN,"mmmm"),JURN3),VALUE) -> 0 | F9: =VLOOKUP(A9,DAF_AKUN,4,FALSE) -> NRC | G9: =IF(D9=TEXT,VALUE,IF(F9="LR",D9,0)) -> 0 | H9: =IF(E9=TEXT,VALUE,IF(F9="LR",E9,0)) -> 0 | I9: =IF(D9=TEXT,VALUE,IF(F9="NRC",D9,0)) -> 0 | J9: =IF(E9=TEXT,VALUE,IF(F9="NRC",E9,0)) -> 0
A10: 1-101-010 | B10: =VLOOKUP(A10,DAF_AKUN,2,FALSE) -> CIMB Niaga - Acc. No: 800171592300 | C10: =VLOOKUP(A10,DAF_AKUN,3,FALSE) -> Db | D10: =IF(AND(ISERROR=TRUE,C10="Db"),SUMIF(AKUN1,A10,AKUN2)+SUMIF(JURN2,"1"&A10,JURN3)-SUMIF(JURN2,"1"&A10,JURN4)+SUMIF(JURN1,A10&TEXT(BLN,"mmmm"),JURN3)-SUMIF(JURN1,A10&TEXT(BLN,"mmmm"),JURN4),VALUE) -> 3043241 | E10: =IF(AND(ISERROR=TRUE,C10="Kr"),SUMIF(AKUN1,A10,AKUN3)-SUMIF(JURN2,"1"&A10,JURN3)+SUMIF(JURN2,"1"&A10,JURN4)+SUMIF(JURN1,A10&TEXT(BLN,"mmmm"),JURN4)-SUMIF(JURN1,A10&TEXT(BLN,"mmmm"),JURN3),VALUE) -> 0 | F10: =VLOOKUP(A10,DAF_AKUN,4,FALSE) -> NRC | G10: =IF(D10=TEXT,VALUE,IF(F10="LR",D10,0)) -> 0 | H10: =IF(E10=TEXT,VALUE,IF(F10="LR",E10,0)) -> 0 | I10: =IF(D10=TEXT,VALUE,IF(F10="NRC",D10,0)) -> 3043241 | J10: =IF(E10=TEXT,VALUE,IF(F10="NRC",E10,0)) -> 0
A11: 1-101-011 | B11: =VLOOKUP(A11,DAF_AKUN,2,FALSE) -> Bank 2 | C11: =VLOOKUP(A11,DAF_AKUN,3,FALSE) -> Db | D11: =IF(AND(ISERROR=TRUE,C11="Db"),SUMIF(AKUN1,A11,AKUN2)+SUMIF(JURN2,"1"&A11,JURN3)-SUMIF(JURN2,"1"&A11,JURN4)+SUMIF(JURN1,A11&TEXT(BLN,"mmmm"),JURN3)-SUMIF(JURN1,A11&TEXT(BLN,"mmmm"),JURN4),VALUE) -> 0 | E11: =IF(AND(ISERROR=TRUE,C11="Kr"),SUMIF(AKUN1,A11,AKUN3)-SUMIF(JURN2,"1"&A11,JURN3)+SUMIF(JURN2,"1"&A11,JURN4)+SUMIF(JURN1,A11&TEXT(BLN,"mmmm"),JURN4)-SUMIF(JURN1,A11&TEXT(BLN,"mmmm"),JURN3),VALUE) -> 0 | F11: =VLOOKUP(A11,DAF_AKUN,4,FALSE) -> NRC | G11: =IF(D11=TEXT,VALUE,IF(F11="LR",D11,0)) -> 0 | H11: =IF(E11=TEXT,VALUE,IF(F11="LR",E11,0)) -> 0 | I11: =IF(D11=TEXT,VALUE,IF(F11="NRC",D11,0)) -> 0 | J11: =IF(E11=TEXT,VALUE,IF(F11="NRC",E11,0)) -> 0
A12: 1-101-012 | B12: =VLOOKUP(A12,DAF_AKUN,2,FALSE) -> Bank 3 | C12: =VLOOKUP(A12,DAF_AKUN,3,FALSE) -> Db | D12: =IF(AND(ISERROR=TRUE,C12="Db"),SUMIF(AKUN1,A12,AKUN2)+SUMIF(JURN2,"1"&A12,JURN3)-SUMIF(JURN2,"1"&A12,JURN4)+SUMIF(JURN1,A12&TEXT(BLN,"mmmm"),JURN3)-SUMIF(JURN1,A12&TEXT(BLN,"mmmm"),JURN4),VALUE) -> 0 | E12: =IF(AND(ISERROR=TRUE,C12="Kr"),SUMIF(AKUN1,A12,AKUN3)-SUMIF(JURN2,"1"&A12,JURN3)+SUMIF(JURN2,"1"&A12,JURN4)+SUMIF(JURN1,A12&TEXT(BLN,"mmmm"),JURN4)-SUMIF(JURN1,A12&TEXT(BLN,"mmmm"),JURN3),VALUE) -> 0 | F12: =VLOOKUP(A12,DAF_AKUN,4,FALSE) -> NRC | G12: =IF(D12=TEXT,VALUE,IF(F12="LR",D12,0)) -> 0 | H12: =IF(E12=TEXT,VALUE,IF(F12="LR",E12,0)) -> 0 | I12: =IF(D12=TEXT,VALUE,IF(F12="NRC",D12,0)) -> 0 | J12: =IF(E12=TEXT,VALUE,IF(F12="NRC",E12,0)) -> 0
A13: 1-101-013 | B13: =VLOOKUP(A13,DAF_AKUN,2,FALSE) -> BAnk 4 | C13: =VLOOKUP(A13,DAF_AKUN,3,FALSE) -> Db | D13: =IF(AND(ISERROR=TRUE,C13="Db"),SUMIF(AKUN1,A13,AKUN2)+SUMIF(JURN2,"1"&A13,JURN3)-SUMIF(JURN2,"1"&A13,JURN4)+SUMIF(JURN1,A13&TEXT(BLN,"mmmm"),JURN3)-SUMIF(JURN1,A13&TEXT(BLN,"mmmm"),JURN4),VALUE) -> 0 | E13: =IF(AND(ISERROR=TRUE,C13="Kr"),SUMIF(AKUN1,A13,AKUN3)-SUMIF(JURN2,"1"&A13,JURN3)+SUMIF(JURN2,"1"&A13,JURN4)+SUMIF(JURN1,A13&TEXT(BLN,"mmmm"),JURN4)-SUMIF(JURN1,A13&TEXT(BLN,"mmmm"),JURN3),VALUE) -> 0 | F13: =VLOOKUP(A13,DAF_AKUN,4,FALSE) -> NRC | G13: =IF(D13=TEXT,VALUE,IF(F13="LR",D13,0)) -> 0 | H13: =IF(E13=TEXT,VALUE,IF(F13="LR",E13,0)) -> 0 | I13: =IF(D13=TEXT,VALUE,IF(F13="NRC",D13,0)) -> 0 | J13: =IF(E13=TEXT,VALUE,IF(F13="NRC",E13,0)) -> 0
A14: 1-101-100 | B14: =VLOOKUP(A14,DAF_AKUN,2,FALSE) -> Bank Deposit | C14: =VLOOKUP(A14,DAF_AKUN,3,FALSE) -> Db | D14: =IF(AND(ISERROR=TRUE,C14="Db"),SUMIF(AKUN1,A14,AKUN2)+SUMIF(JURN2,"1"&A14,JURN3)-SUMIF(JURN2,"1"&A14,JURN4)+SUMIF(JURN1,A14&TEXT(BLN,"mmmm"),JURN3)-SUMIF(JURN1,A14&TEXT(BLN,"mmmm"),JURN4),VALUE) -> 0 | E14: =IF(AND(ISERROR=TRUE,C14="Kr"),SUMIF(AKUN1,A14,AKUN3)-SUMIF(JURN2,"1"&A14,JURN3)+SUMIF(JURN2,"1"&A14,JURN4)+SUMIF(JURN1,A14&TEXT(BLN,"mmmm"),JURN4)-SUMIF(JURN1,A14&TEXT(BLN,"mmmm"),JURN3),VALUE) -> 0 | F14: =VLOOKUP(A14,DAF_AKUN,4,FALSE) -> NRC | G14: =IF(D14=TEXT,VALUE,IF(F14="LR",D14,0)) -> 0 | H14: =IF(E14=TEXT,VALUE,IF(F14="LR",E14,0)) -> 0 | I14: =IF(D14=TEXT,VALUE,IF(F14="NRC",D14,0)) -> 0 | J14: =IF(E14=TEXT,VALUE,IF(F14="NRC",E14,0)) -> 0
A15: 1-101-101 | B15: =VLOOKUP(A15,DAF_AKUN,2,FALSE) -> Others Deposit | C15: =VLOOKUP(A15,DAF_AKUN,3,FALSE) -> Db | D15: =IF(AND(ISERROR=TRUE,C15="Db"),SUMIF(AKUN1,A15,AKUN2)+SUMIF(JURN2,"1"&A15,JURN3)-SUMIF(JURN2,"1"&A15,JURN4)+SUMIF(JURN1,A15&TEXT(BLN,"mmmm"),JURN3)-SUMIF(JURN1,A15&TEXT(BLN,"mmmm"),JURN4),VALUE) -> 0 | E15: =IF(AND(ISERROR=TRUE,C15="Kr"),SUMIF(AKUN1,A15,AKUN3)-SUMIF(JURN2,"1"&A15,JURN3)+SUMIF(JURN2,"1"&A15,JURN4)+SUMIF(JURN1,A15&TEXT(BLN,"mmmm"),JURN4)-SUMIF(JURN1,A15&TEXT(BLN,"mmmm"),JURN3),VALUE) -> 0 | F15: =VLOOKUP(A15,DAF_AKUN,4,FALSE) -> NRC | G15: =IF(D15=TEXT,VALUE,IF(F15="LR",D15,0)) -> 0 | H15: =IF(E15=TEXT,VALUE,IF(F15="LR",E15,0)) -> 0 | I15: =IF(D15=TEXT,VALUE,IF(F15="NRC",D15,0)) -> 0 | J15: =IF(E15=TEXT,VALUE,IF(F15="NRC",E15,0)) -> 0
A16: 1-101-200 | B16: =VLOOKUP(A16,DAF_AKUN,2,FALSE) -> Cash In Transit | C16: =VLOOKUP(A16,DAF_AKUN,3,FALSE) -> Db | D16: =IF(AND(ISERROR=TRUE,C16="Db"),SUMIF(AKUN1,A16,AKUN2)+SUMIF(JURN2,"1"&A16,JURN3)-SUMIF(JURN2,"1"&A16,JURN4)+SUMIF(JURN1,A16&TEXT(BLN,"mmmm"),JURN3)-SUMIF(JURN1,A16&TEXT(BLN,"mmmm"),JURN4),VALUE) -> 0 | E16: =IF(AND(ISERROR=TRUE,C16="Kr"),SUMIF(AKUN1,A16,AKUN3)-SUMIF(JURN2,"1"&A16,JURN3)+SUMIF(JURN2,"1"&A16,JURN4)+SUMIF(JURN1,A16&TEXT(BLN,"mmmm"),JURN4)-SUMIF(JURN1,A16&TEXT(BLN,"mmmm"),JURN3),VALUE) -> 0 | F16: =VLOOKUP(A16,DAF_AKUN,4,FALSE) -> NRC | G16: =IF(D16=TEXT,VALUE,IF(F16="LR",D16,0)) -> 0 | H16: =IF(E16=TEXT,VALUE,IF(F16="LR",E16,0)) -> 0 | I16: =IF(D16=TEXT,VALUE,IF(F16="NRC",D16,0)) -> 0 | J16: =IF(E16=TEXT,VALUE,IF(F16="NRC",E16,0)) -> 0
A17: 1-102-000 | B17: =VLOOKUP(A17,DAF_AKUN,2,FALSE) -> Account Receivable | C17: =VLOOKUP(A17,DAF_AKUN,3,FALSE) -> Db | D17: =IF(AND(ISERROR=TRUE,C17="Db"),SUMIF(AKUN1,A17,AKUN2)+SUMIF(JURN2,"1"&A17,JURN3)-SUMIF(JURN2,"1"&A17,JURN4)+SUMIF(JURN1,A17&TEXT(BLN,"mmmm"),JURN3)-SUMIF(JURN1,A17&TEXT(BLN,"mmmm"),JURN4),VALUE) -> 0 | E17: =IF(AND(ISERROR=TRUE,C17="Kr"),SUMIF(AKUN1,A17,AKUN3)-SUMIF(JURN2,"1"&A17,JURN3)+SUMIF(JURN2,"1"&A17,JURN4)+SUMIF(JURN1,A17&TEXT(BLN,"mmmm"),JURN4)-SUMIF(JURN1,A17&TEXT(BLN,"mmmm"),JURN3),VALUE) -> 0 | F17: =VLOOKUP(A17,DAF_AKUN,4,FALSE) -> NRC | G17: =IF(D17=TEXT,VALUE,IF(F17="LR",D17,0)) -> 0 | H17: =IF(E17=TEXT,VALUE,IF(F17="LR",E17,0)) -> 0 | I17: =IF(D17=TEXT,VALUE,IF(F17="NRC",D17,0)) -> 0 | J17: =IF(E17=TEXT,VALUE,IF(F17="NRC",E17,0)) -> 0
A18: 1-102-001 | B18: =VLOOKUP(A18,DAF_AKUN,2,FALSE) -> Receivable - Trade | C18: =VLOOKUP(A18,DAF_AKUN,3,FALSE) -> Db | D18: =IF(AND(ISERROR=TRUE,C18="Db"),SUMIF(AKUN1,A18,AKUN2)+SUMIF(JURN2,"1"&A18,JURN3)-SUMIF(JURN2,"1"&A18,JURN4)+SUMIF(JURN1,A18&TEXT(BLN,"mmmm"),JURN3)-SUMIF(JURN1,A18&TEXT(BLN,"mmmm"),JURN4),VALUE) -> 277134525 | E18: =IF(AND(ISERROR=TRUE,C18="Kr"),SUMIF(AKUN1,A18,AKUN3)-SUMIF(JURN2,"1"&A18,JURN3)+SUMIF(JURN2,"1"&A18,JURN4)+SUMIF(JURN1,A18&TEXT(BLN,"mmmm"),JURN4)-SUMIF(JURN1,A18&TEXT(BLN,"mmmm"),JURN3),VALUE) -> 0 | F18: =VLOOKUP(A18,DAF_AKUN,4,FALSE) -> NRC | G18: =IF(D18=TEXT,VALUE,IF(F18="LR",D18,0)) -> 0 | H18: =IF(E18=TEXT,VALUE,IF(F18="LR",E18,0)) -> 0 | I18: =IF(D18=TEXT,VALUE,IF(F18="NRC",D18,0)) -> 277134525 | J18: =IF(E18=TEXT,VALUE,IF(F18="NRC",E18,0)) -> 0
A19: 1-102-002 | B19: =VLOOKUP(A19,DAF_AKUN,2,FALSE) -> Employee Receivable | C19: =VLOOKUP(A19,DAF_AKUN,3,FALSE) -> Db | D19: =IF(AND(ISERROR=TRUE,C19="Db"),SUMIF(AKUN1,A19,AKUN2)+SUMIF(JURN2,"1"&A19,JURN3)-SUMIF(JURN2,"1"&A19,JURN4)+SUMIF(JURN1,A19&TEXT(BLN,"mmmm"),JURN3)-SUMIF(JURN1,A19&TEXT(BLN,"mmmm"),JURN4),VALUE) -> 0 | E19: =IF(AND(ISERROR=TRUE,C19="Kr"),SUMIF(AKUN1,A19,AKUN3)-SUMIF(JURN2,"1"&A19,JURN3)+SUMIF(JURN2,"1"&A19,JURN4)+SUMIF(JURN1,A19&TEXT(BLN,"mmmm"),JURN4)-SUMIF(JURN1,A19&TEXT(BLN,"mmmm"),JURN3),VALUE) -> 0 | F19: =VLOOKUP(A19,DAF_AKUN,4,FALSE) -> NRC | G19: =IF(D19=TEXT,VALUE,IF(F19="LR",D19,0)) -> 0 | H19: =IF(E19=TEXT,VALUE,IF(F19="LR",E19,0)) -> 0 | I19: =IF(D19=TEXT,VALUE,IF(F19="NRC",D19,0)) -> 0 | J19: =IF(E19=TEXT,VALUE,IF(F19="NRC",E19,0)) -> 0
... A86: 3-102-003 | B86: =VLOOKUP(A86,DAF_AKUN,2,FALSE) -> Current Year Profit/(Loss) | C86: =VLOOKUP(A86,DAF_AKUN,3,FALSE) -> Kr | D86: =IF(AND(ISERROR=TRUE,C86="Db"),SUMIF(AKUN1,A86,AKUN2)+SUMIF(JURN2,"1"&A86,JURN3)-SUMIF(JURN2,"1"&A86,JURN4)+SUMIF(JURN1,A86&TEXT(BLN,"mmmm"),JURN3)-SUMIF(JURN1,A86&TEXT(BLN,"mmmm"),JURN4),VALUE) -> 0 | E86: =IF(AND(ISERROR=TRUE,C86="Kr"),SUMIF(AKUN1,A86,AKUN3)-SUMIF(JURN2,"1"&A86,JURN3)+SUMIF(JURN2,"1"&A86,JURN4)+SUMIF(JURN1,A86&TEXT(BLN,"mmmm"),JURN4)-SUMIF(JURN1,A86&TEXT(BLN,"mmmm"),JURN3),VALUE) -> 0 | F86: =VLOOKUP(A86,DAF_AKUN,4,FALSE) -> NRC | G86: =IF(D86=TEXT,VALUE,IF(F86="LR",D86,0)) -> 0 | H86: =IF(E86=TEXT,VALUE,IF(F86="LR",E86,0)) -> 0 | I86: =IF(D86=TEXT,VALUE,IF(F86="NRC",D86,0)) -> 0 | J86: =IF(E86=TEXT,VALUE,IF(F86="NRC",E86,0)) -> 0
A87: 3-102-004 | B87: Ekuitas Lainnya | C87: Kr | D87: =IF(AND(ISERROR=TRUE,C87="Db"),SUMIF(AKUN1,A87,AKUN2)+SUMIF(JURN2,"1"&A87,JURN3)-SUMIF(JURN2,"1"&A87,JURN4)+SUMIF(JURN1,A87&TEXT(BLN,"mmmm"),JURN3)-SUMIF(JURN1,A87&TEXT(BLN,"mmmm"),JURN4),VALUE) -> 0 | E87: =IF(AND(ISERROR=TRUE,C87="Kr"),SUMIF(AKUN1,A87,AKUN3)-SUMIF(JURN2,"1"&A87,JURN3)+SUMIF(JURN2,"1"&A87,JURN4)+SUMIF(JURN1,A87&TEXT(BLN,"mmmm"),JURN4)-SUMIF(JURN1,A87&TEXT(BLN,"mmmm"),JURN3),VALUE) -> 19663808 | F87: NRC | G87: =IF(D87=TEXT,VALUE,IF(F87="LR",D87,0)) -> 0 | H87: =IF(E87=TEXT,VALUE,IF(F87="LR",E87,0)) -> 0 | I87: =IF(D87=TEXT,VALUE,IF(F87="NRC",D87,0)) -> 0 | J87: =IF(E87=TEXT,VALUE,IF(F87="NRC",E87,0)) -> 19663808
A88: 4-100-000 | B88: =VLOOKUP(A88,DAF_AKUN,2,FALSE) -> Total Revenue | C88: =VLOOKUP(A88,DAF_AKUN,3,FALSE) -> Kr | D88: =IF(AND(ISERROR=TRUE,C88="Db"),SUMIF(AKUN1,A88,AKUN2)+SUMIF(JURN2,"1"&A88,JURN3)-SUMIF(JURN2,"1"&A88,JURN4)+SUMIF(JURN1,A88&TEXT(BLN,"mmmm"),JURN3)-SUMIF(JURN1,A88&TEXT(BLN,"mmmm"),JURN4),VALUE) -> 0 | E88: =IF(AND(ISERROR=TRUE,C88="Kr"),SUMIF(AKUN1,A88,AKUN3)-SUMIF(JURN2,"1"&A88,JURN3)+SUMIF(JURN2,"1"&A88,JURN4)+SUMIF(JURN1,A88&TEXT(BLN,"mmmm"),JURN4)-SUMIF(JURN1,A88&TEXT(BLN,"mmmm"),JURN3),VALUE) -> 0 | F88: =VLOOKUP(A88,DAF_AKUN,4,FALSE) -> LR | G88: =IF(D88=TEXT,VALUE,IF(F88="LR",D88,0)) -> 0 | H88: =IF(E88=TEXT,VALUE,IF(F88="LR",E88,0)) -> 0 | I88: =IF(D88=TEXT,VALUE,IF(F88="NRC",D88,0)) -> 0 | J88: =IF(E88=TEXT,VALUE,IF(F88="NRC",E88,0)) -> 0
A89: 4-101-000 | B89: =VLOOKUP(A89,DAF_AKUN,2,FALSE) -> Total Event Management Services Income | C89: =VLOOKUP(A89,DAF_AKUN,3,FALSE) -> Kr | D89: =IF(AND(ISERROR=TRUE,C89="Db"),SUMIF(AKUN1,A89,AKUN2)+SUMIF(JURN2,"1"&A89,JURN3)-SUMIF(JURN2,"1"&A89,JURN4)+SUMIF(JURN1,A89&TEXT(BLN,"mmmm"),JURN3)-SUMIF(JURN1,A89&TEXT(BLN,"mmmm"),JURN4),VALUE) -> 0 | E89: =IF(AND(ISERROR=TRUE,C89="Kr"),SUMIF(AKUN1,A89,AKUN3)-SUMIF(JURN2,"1"&A89,JURN3)+SUMIF(JURN2,"1"&A89,JURN4)+SUMIF(JURN1,A89&TEXT(BLN,"mmmm"),JURN4)-SUMIF(JURN1,A89&TEXT(BLN,"mmmm"),JURN3),VALUE) -> 0 | F89: =VLOOKUP(A89,DAF_AKUN,4,FALSE) -> LR | G89: =IF(D89=TEXT,VALUE,IF(F89="LR",D89,0)) -> 0 | H89: =IF(E89=TEXT,VALUE,IF(F89="LR",E89,0)) -> 0 | I89: =IF(D89=TEXT,VALUE,IF(F89="NRC",D89,0)) -> 0 | J89: =IF(E89=TEXT,VALUE,IF(F89="NRC",E89,0)) -> 0
A90: 4-101-001 | B90: =VLOOKUP(A90,DAF_AKUN,2,FALSE) -> Pendapatan Usaha | C90: =VLOOKUP(A90,DAF_AKUN,3,FALSE) -> Kr | D90: =IF(AND(ISERROR=TRUE,C90="Db"),SUMIF(AKUN1,A90,AKUN2)+SUMIF(JURN2,"1"&A90,JURN3)-SUMIF(JURN2,"1"&A90,JURN4)+SUMIF(JURN1,A90&TEXT(BLN,"mmmm"),JURN3)-SUMIF(JURN1,A90&TEXT(BLN,"mmmm"),JURN4),VALUE) -> 0 | E90: =IF(AND(ISERROR=TRUE,C90="Kr"),SUMIF(AKUN1,A90,AKUN3)-SUMIF(JURN2,"1"&A90,JURN3)+SUMIF(JURN2,"1"&A90,JURN4)+SUMIF(JURN1,A90&TEXT(BLN,"mmmm"),JURN4)-SUMIF(JURN1,A90&TEXT(BLN,"mmmm"),JURN3),VALUE) -> 310838800 | F90: =VLOOKUP(A90,DAF_AKUN,4,FALSE) -> LR | G90: =IF(D90=TEXT,VALUE,IF(F90="LR",D90,0)) -> 0 | H90: =IF(E90=TEXT,VALUE,IF(F90="LR",E90,0)) -> 310838800 | I90: =IF(D90=TEXT,VALUE,IF(F90="NRC",D90,0)) -> 0 | J90: =IF(E90=TEXT,VALUE,IF(F90="NRC",E90,0)) -> 0
A91: 4-101-002 | B91: =VLOOKUP(A91,DAF_AKUN,2,FALSE) -> Pendapatan .... | C91: =VLOOKUP(A91,DAF_AKUN,3,FALSE) -> Kr | D91: =IF(AND(ISERROR=TRUE,C91="Db"),SUMIF(AKUN1,A91,AKUN2)+SUMIF(JURN2,"1"&A91,JURN3)-SUMIF(JURN2,"1"&A91,JURN4)+SUMIF(JURN1,A91&TEXT(BLN,"mmmm"),JURN3)-SUMIF(JURN1,A91&TEXT(BLN,"mmmm"),JURN4),VALUE) -> 0 | E91: =IF(AND(ISERROR=TRUE,C91="Kr"),SUMIF(AKUN1,A91,AKUN3)-SUMIF(JURN2,"1"&A91,JURN3)+SUMIF(JURN2,"1"&A91,JURN4)+SUMIF(JURN1,A91&TEXT(BLN,"mmmm"),JURN4)-SUMIF(JURN1,A91&TEXT(BLN,"mmmm"),JURN3),VALUE) -> 0 | F91: =VLOOKUP(A91,DAF_AKUN,4,FALSE) -> LR | G91: =IF(D91=TEXT,VALUE,IF(F91="LR",D91,0)) -> 0 | H91: =IF(E91=TEXT,VALUE,IF(F91="LR",E91,0)) -> 0 | I91: =IF(D91=TEXT,VALUE,IF(F91="NRC",D91,0)) -> 0 | J91: =IF(E91=TEXT,VALUE,IF(F91="NRC",E91,0)) -> 0
A92: 4-101-003 | B92: =VLOOKUP(A92,DAF_AKUN,2,FALSE) -> Pendapatan .... | C92: =VLOOKUP(A92,DAF_AKUN,3,FALSE) -> Kr | D92: =IF(AND(ISERROR=TRUE,C92="Db"),SUMIF(AKUN1,A92,AKUN2)+SUMIF(JURN2,"1"&A92,JURN3)-SUMIF(JURN2,"1"&A92,JURN4)+SUMIF(JURN1,A92&TEXT(BLN,"mmmm"),JURN3)-SUMIF(JURN1,A92&TEXT(BLN,"mmmm"),JURN4),VALUE) -> 0 | E92: =IF(AND(ISERROR=TRUE,C92="Kr"),SUMIF(AKUN1,A92,AKUN3)-SUMIF(JURN2,"1"&A92,JURN3)+SUMIF(JURN2,"1"&A92,JURN4)+SUMIF(JURN1,A92&TEXT(BLN,"mmmm"),JURN4)-SUMIF(JURN1,A92&TEXT(BLN,"mmmm"),JURN3),VALUE) -> 0 | F92: =VLOOKUP(A92,DAF_AKUN,4,FALSE) -> LR | G92: =IF(D92=TEXT,VALUE,IF(F92="LR",D92,0)) -> 0 | H92: =IF(E92=TEXT,VALUE,IF(F92="LR",E92,0)) -> 0 | I92: =IF(D92=TEXT,VALUE,IF(F92="NRC",D92,0)) -> 0 | J92: =IF(E92=TEXT,VALUE,IF(F92="NRC",E92,0)) -> 0
A93: 4-101-004 | B93: =VLOOKUP(A93,DAF_AKUN,2,FALSE) -> Pendapatan .... | C93: =VLOOKUP(A93,DAF_AKUN,3,FALSE) -> Kr | D93: =IF(AND(ISERROR=TRUE,C93="Db"),SUMIF(AKUN1,A93,AKUN2)+SUMIF(JURN2,"1"&A93,JURN3)-SUMIF(JURN2,"1"&A93,JURN4)+SUMIF(JURN1,A93&TEXT(BLN,"mmmm"),JURN3)-SUMIF(JURN1,A93&TEXT(BLN,"mmmm"),JURN4),VALUE) -> 0 | E93: =IF(AND(ISERROR=TRUE,C93="Kr"),SUMIF(AKUN1,A93,AKUN3)-SUMIF(JURN2,"1"&A93,JURN3)+SUMIF(JURN2,"1"&A93,JURN4)+SUMIF(JURN1,A93&TEXT(BLN,"mmmm"),JURN4)-SUMIF(JURN1,A93&TEXT(BLN,"mmmm"),JURN3),VALUE) -> 0 | F93: =VLOOKUP(A93,DAF_AKUN,4,FALSE) -> LR | G93: =IF(D93=TEXT,VALUE,IF(F93="LR",D93,0)) -> 0 | H93: =IF(E93=TEXT,VALUE,IF(F93="LR",E93,0)) -> 0 | I93: =IF(D93=TEXT,VALUE,IF(F93="NRC",D93,0)) -> 0 | J93: =IF(E93=TEXT,VALUE,IF(F93="NRC",E93,0)) -> 0
A94: 4-101-005 | B94: =VLOOKUP(A94,DAF_AKUN,2,FALSE) -> Pendapatan .... | C94: =VLOOKUP(A94,DAF_AKUN,3,FALSE) -> Kr | D94: =IF(AND(ISERROR=TRUE,C94="Db"),SUMIF(AKUN1,A94,AKUN2)+SUMIF(JURN2,"1"&A94,JURN3)-SUMIF(JURN2,"1"&A94,JURN4)+SUMIF(JURN1,A94&TEXT(BLN,"mmmm"),JURN3)-SUMIF(JURN1,A94&TEXT(BLN,"mmmm"),JURN4),VALUE) -> 0 | E94: =IF(AND(ISERROR=TRUE,C94="Kr"),SUMIF(AKUN1,A94,AKUN3)-SUMIF(JURN2,"1"&A94,JURN3)+SUMIF(JURN2,"1"&A94,JURN4)+SUMIF(JURN1,A94&TEXT(BLN,"mmmm"),JURN4)-SUMIF(JURN1,A94&TEXT(BLN,"mmmm"),JURN3),VALUE) -> 0 | F94: =VLOOKUP(A94,DAF_AKUN,4,FALSE) -> LR | G94: =IF(D94=TEXT,VALUE,IF(F94="LR",D94,0)) -> 0 | H94: =IF(E94=TEXT,VALUE,IF(F94="LR",E94,0)) -> 0 | I94: =IF(D94=TEXT,VALUE,IF(F94="NRC",D94,0)) -> 0 | J94: =IF(E94=TEXT,VALUE,IF(F94="NRC",E94,0)) -> 0
A95: 4-101-006 | B95: =VLOOKUP(A95,DAF_AKUN,2,FALSE) -> Pendapatan .... | C95: =VLOOKUP(A95,DAF_AKUN,3,FALSE) -> Kr | D95: =IF(AND(ISERROR=TRUE,C95="Db"),SUMIF(AKUN1,A95,AKUN2)+SUMIF(JURN2,"1"&A95,JURN3)-SUMIF(JURN2,"1"&A95,JURN4)+SUMIF(JURN1,A95&TEXT(BLN,"mmmm"),JURN3)-SUMIF(JURN1,A95&TEXT(BLN,"mmmm"),JURN4),VALUE) -> 0 | E95: =IF(AND(ISERROR=TRUE,C95="Kr"),SUMIF(AKUN1,A95,AKUN3)-SUMIF(JURN2,"1"&A95,JURN3)+SUMIF(JURN2,"1"&A95,JURN4)+SUMIF(JURN1,A95&TEXT(BLN,"mmmm"),JURN4)-SUMIF(JURN1,A95&TEXT(BLN,"mmmm"),JURN3),VALUE) -> 0 | F95: =VLOOKUP(A95,DAF_AKUN,4,FALSE) -> LR | G95: =IF(D95=TEXT,VALUE,IF(F95="LR",D95,0)) -> 0 | H95: =IF(E95=TEXT,VALUE,IF(F95="LR",E95,0)) -> 0 | I95: =IF(D95=TEXT,VALUE,IF(F95="NRC",D95,0)) -> 0 | J95: =IF(E95=TEXT,VALUE,IF(F95="NRC",E95,0)) -> 0
A96: 4-101-007 | B96: =VLOOKUP(A96,DAF_AKUN,2,FALSE) -> Pendapatan .... | C96: =VLOOKUP(A96,DAF_AKUN,3,FALSE) -> Kr | D96: =IF(AND(ISERROR=TRUE,C96="Db"),SUMIF(AKUN1,A96,AKUN2)+SUMIF(JURN2,"1"&A96,JURN3)-SUMIF(JURN2,"1"&A96,JURN4)+SUMIF(JURN1,A96&TEXT(BLN,"mmmm"),JURN3)-SUMIF(JURN1,A96&TEXT(BLN,"mmmm"),JURN4),VALUE) -> 0 | E96: =IF(AND(ISERROR=TRUE,C96="Kr"),SUMIF(AKUN1,A96,AKUN3)-SUMIF(JURN2,"1"&A96,JURN3)+SUMIF(JURN2,"1"&A96,JURN4)+SUMIF(JURN1,A96&TEXT(BLN,"mmmm"),JURN4)-SUMIF(JURN1,A96&TEXT(BLN,"mmmm"),JURN3),VALUE) -> 0 | F96: =VLOOKUP(A96,DAF_AKUN,4,FALSE) -> LR | G96: =IF(D96=TEXT,VALUE,IF(F96="LR",D96,0)) -> 0 | H96: =IF(E96=TEXT,VALUE,IF(F96="LR",E96,0)) -> 0 | I96: =IF(D96=TEXT,VALUE,IF(F96="NRC",D96,0)) -> 0 | J96: =IF(E96=TEXT,VALUE,IF(F96="NRC",E96,0)) -> 0
A97: 4-101-008 | B97: =VLOOKUP(A97,DAF_AKUN,2,FALSE) -> Pendapatan .... | C97: =VLOOKUP(A97,DAF_AKUN,3,FALSE) -> Kr | D97: =IF(AND(ISERROR=TRUE,C97="Db"),SUMIF(AKUN1,A97,AKUN2)+SUMIF(JURN2,"1"&A97,JURN3)-SUMIF(JURN2,"1"&A97,JURN4)+SUMIF(JURN1,A97&TEXT(BLN,"mmmm"),JURN3)-SUMIF(JURN1,A97&TEXT(BLN,"mmmm"),JURN4),VALUE) -> 0 | E97: =IF(AND(ISERROR=TRUE,C97="Kr"),SUMIF(AKUN1,A97,AKUN3)-SUMIF(JURN2,"1"&A97,JURN3)+SUMIF(JURN2,"1"&A97,JURN4)+SUMIF(JURN1,A97&TEXT(BLN,"mmmm"),JURN4)-SUMIF(JURN1,A97&TEXT(BLN,"mmmm"),JURN3),VALUE) -> 0 | F97: =VLOOKUP(A97,DAF_AKUN,4,FALSE) -> LR | G97: =IF(D97=TEXT,VALUE,IF(F97="LR",D97,0)) -> 0 | H97: =IF(E97=TEXT,VALUE,IF(F97="LR",E97,0)) -> 0 | I97: =IF(D97=TEXT,VALUE,IF(F97="NRC",D97,0)) -> 0 | J97: =IF(E97=TEXT,VALUE,IF(F97="NRC",E97,0)) -> 0
A98: 4-101-020 | B98: =VLOOKUP(A98,DAF_AKUN,2,FALSE) -> Pendapatan .... | C98: =VLOOKUP(A98,DAF_AKUN,3,FALSE) -> Kr | D98: =IF(AND(ISERROR=TRUE,C98="Db"),SUMIF(AKUN1,A98,AKUN2)+SUMIF(JURN2,"1"&A98,JURN3)-SUMIF(JURN2,"1"&A98,JURN4)+SUMIF(JURN1,A98&TEXT(BLN,"mmmm"),JURN3)-SUMIF(JURN1,A98&TEXT(BLN,"mmmm"),JURN4),VALUE) -> 0 | E98: =IF(AND(ISERROR=TRUE,C98="Kr"),SUMIF(AKUN1,A98,AKUN3)-SUMIF(JURN2,"1"&A98,JURN3)+SUMIF(JURN2,"1"&A98,JURN4)+SUMIF(JURN1,A98&TEXT(BLN,"mmmm"),JURN4)-SUMIF(JURN1,A98&TEXT(BLN,"mmmm"),JURN3),VALUE) -> 0 | F98: =VLOOKUP(A98,DAF_AKUN,4,FALSE) -> LR | G98: =IF(D98=TEXT,VALUE,IF(F98="LR",D98,0)) -> 0 | H98: =IF(E98=TEXT,VALUE,IF(F98="LR",E98,0)) -> 0 | I98: =IF(D98=TEXT,VALUE,IF(F98="NRC",D98,0)) -> 0 | J98: =IF(E98=TEXT,VALUE,IF(F98="NRC",E98,0)) -> 0
A99: 4-101-100 | B99: =VLOOKUP(A99,DAF_AKUN,2,FALSE) -> Agency Service Fee | C99: =VLOOKUP(A99,DAF_AKUN,3,FALSE) -> Kr | D99: =IF(AND(ISERROR=TRUE,C99="Db"),SUMIF(AKUN1,A99,AKUN2)+SUMIF(JURN2,"1"&A99,JURN3)-SUMIF(JURN2,"1"&A99,JURN4)+SUMIF(JURN1,A99&TEXT(BLN,"mmmm"),JURN3)-SUMIF(JURN1,A99&TEXT(BLN,"mmmm"),JURN4),VALUE) -> 0 | E99: =IF(AND(ISERROR=TRUE,C99="Kr"),SUMIF(AKUN1,A99,AKUN3)-SUMIF(JURN2,"1"&A99,JURN3)+SUMIF(JURN2,"1"&A99,JURN4)+SUMIF(JURN1,A99&TEXT(BLN,"mmmm"),JURN4)-SUMIF(JURN1,A99&TEXT(BLN,"mmmm"),JURN3),VALUE) -> 0 | F99: =VLOOKUP(A99,DAF_AKUN,4,FALSE) -> LR | G99: =IF(D99=TEXT,VALUE,IF(F99="LR",D99,0)) -> 0 | H99: =IF(E99=TEXT,VALUE,IF(F99="LR",E99,0)) -> 0 | I99: =IF(D99=TEXT,VALUE,IF(F99="NRC",D99,0)) -> 0 | J99: =IF(E99=TEXT,VALUE,IF(F99="NRC",E99,0)) -> 0
... A200: 9-102-001 | B200: =VLOOKUP(A200,DAF_AKUN,2,FALSE) -> Dividend Expense | C200: =VLOOKUP(A200,DAF_AKUN,3,FALSE) -> Db | D200: =IF(AND(ISERROR=TRUE,C200="Db"),SUMIF(AKUN1,A200,AKUN2)+SUMIF(JURN2,"1"&A200,JURN3)-SUMIF(JURN2,"1"&A200,JURN4)+SUMIF(JURN1,A200&TEXT(BLN,"mmmm"),JURN3)-SUMIF(JURN1,A200&TEXT(BLN,"mmmm"),JURN4),VALUE) -> 0 | E200: =IF(AND(ISERROR=TRUE,C200="Kr"),SUMIF(AKUN1,A200,AKUN3)-SUMIF(JURN2,"1"&A200,JURN3)+SUMIF(JURN2,"1"&A200,JURN4)+SUMIF(JURN1,A200&TEXT(BLN,"mmmm"),JURN4)-SUMIF(JURN1,A200&TEXT(BLN,"mmmm"),JURN3),VALUE) -> 0 | F200: =VLOOKUP(A200,DAF_AKUN,4,FALSE) -> LR | G200: =IF(D200=TEXT,VALUE,IF(F200="LR",D200,0)) -> 0 | H200: =IF(E200=TEXT,VALUE,IF(F200="LR",E200,0)) -> 0 | I200: =IF(D200=TEXT,VALUE,IF(F200="NRC",D200,0)) -> 0 | J200: =IF(E200=TEXT,VALUE,IF(F200="NRC",E200,0)) -> 0
B203: Jumlah | D203: =SUM(D7:D202) -> 336505308 | E203: =SUM(E7:E202) -> 336505308 | G203: =SUM(G7:G202) -> 47253253 | H203: =SUM(H7:H202) -> 310838800 | I203: =SUM(I7:I202) -> 289252055 | J203: =SUM(J7:J202) -> 25666508
B204: Laba (Rugi) Bersih | H204: =H203-G203 -> 263585547 | J204: =H204 -> 263585547
B205: Jumlah | I205: =SUM(I203:I204) -> 289252055 | J205: =SUM(J203:J204) -> 289252055
E206: =D203-E203 -> 0

Sheet Index
A1: =DATE(0,B1,1) -> 1 | B1: 1 | D1: =IF(User!D6=D4,0,"#") -> 0 | F1: =IF(OR(INDEX(Kode!C:C,0,1)="Piutang",INDEX(Kode!C:C,0,1)="Hutang"),INDEX(Kode!A:A,0,1),"") | G1: =IF(OR(INDEX(Akun!C:C,0,1)="Db",INDEX(Akun!C:C,0,1)="Kr"),INDEX(Akun!A:A,0,1),"")
A2: =DATE(0,B2,1) -> 32 | B2: 2 | D2: =User!D6=D4 -> TRUE | F2: =IF(OR(INDEX(Kode!C:C,0,1)="Piutang",INDEX(Kode!C:C,0,1)="Hutang"),INDEX(Kode!A:A,0,1),"") | G2: =IF(OR(INDEX(Akun!C:C,0,1)="Db",INDEX(Akun!C:C,0,1)="Kr"),INDEX(Akun!A:A,0,1),"")
A3: =DATE(0,B3,1) -> 61 | B3: 3 | D3: =IF(User!D6=D4,"-","#") -> - | F3: =IF(OR(INDEX(Kode!C:C,0,1)="Piutang",INDEX(Kode!C:C,0,1)="Hutang"),INDEX(Kode!A:A,0,1),"") | G3: =IF(OR(INDEX(Akun!C:C,0,1)="Db",INDEX(Akun!C:C,0,1)="Kr"),INDEX(Akun!A:A,0,1),"")
A4: =DATE(0,B4,1) -> 92 | B4: 4 | D4: GL-2468907531-XCL | F4: =IF(OR(INDEX(Kode!C:C,0,1)="Piutang",INDEX(Kode!C:C,0,1)="Hutang"),INDEX(Kode!A:A,0,1),"") | G4: =IF(OR(INDEX(Akun!C:C,0,1)="Db",INDEX(Akun!C:C,0,1)="Kr"),INDEX(Akun!A:A,0,1),"")
A5: =DATE(0,B5,1) -> 122 | B5: 5 | F5: =IF(OR(INDEX(Kode!C:C,0,1)="Piutang",INDEX(Kode!C:C,0,1)="Hutang"),INDEX(Kode!A:A,0,1),"") | G5: =IF(OR(INDEX(Akun!C:C,0,1)="Db",INDEX(Akun!C:C,0,1)="Kr"),INDEX(Akun!A:A,0,1),"")
A6: =DATE(0,B6,1) -> 153 | B6: 6 | F6: =IF(OR(INDEX(Kode!C:C,0,1)="Piutang",INDEX(Kode!C:C,0,1)="Hutang"),INDEX(Kode!A:A,0,1),"") | G6: =IF(OR(INDEX(Akun!C:C,0,1)="Db",INDEX(Akun!C:C,0,1)="Kr"),INDEX(Akun!A:A,0,1),"")
A7: =DATE(0,B7,1) -> 183 | B7: 7 | F7: =IF(OR(INDEX(Kode!C:C,0,1)="Piutang",INDEX(Kode!C:C,0,1)="Hutang"),INDEX(Kode!A:A,0,1),"") | G7: =IF(OR(INDEX(Akun!C:C,0,1)="Db",INDEX(Akun!C:C,0,1)="Kr"),INDEX(Akun!A:A,0,1),"")
A8: =DATE(0,B8,1) -> 214 | B8: 8 | F8: =IF(OR(INDEX(Kode!C:C,0,1)="Piutang",INDEX(Kode!C:C,0,1)="Hutang"),INDEX(Kode!A:A,0,1),"") | G8: =IF(OR(INDEX(Akun!C:C,0,1)="Db",INDEX(Akun!C:C,0,1)="Kr"),INDEX(Akun!A:A,0,1),"")
A9: =DATE(0,B9,1) -> 245 | B9: 9 | F9: =IF(OR(INDEX(Kode!C:C,0,1)="Piutang",INDEX(Kode!C:C,0,1)="Hutang"),INDEX(Kode!A:A,0,1),"") | G9: =IF(OR(INDEX(Akun!C:C,0,1)="Db",INDEX(Akun!C:C,0,1)="Kr"),INDEX(Akun!A:A,0,1),"") -> 1-101-000
A10: =DATE(0,B10,1) -> 275 | B10: 10 | F10: =IF(OR(INDEX(Kode!C:C,0,1)="Piutang",INDEX(Kode!C:C,0,1)="Hutang"),INDEX(Kode!A:A,0,1),"") | G10: =IF(OR(INDEX(Akun!C:C,0,1)="Db",INDEX(Akun!C:C,0,1)="Kr"),INDEX(Akun!A:A,0,1),"") -> 1-101-001
A11: =DATE(0,B11,1) -> 306 | B11: 11 | F11: =IF(OR(INDEX(Kode!C:C,0,1)="Piutang",INDEX(Kode!C:C,0,1)="Hutang"),INDEX(Kode!A:A,0,1),"") | G11: =IF(OR(INDEX(Akun!C:C,0,1)="Db",INDEX(Akun!C:C,0,1)="Kr"),INDEX(Akun!A:A,0,1),"") -> 1-101-010
A12: =DATE(0,B12,1) -> 336 | B12: 12 | F12: =IF(OR(INDEX(Kode!C:C,0,1)="Piutang",INDEX(Kode!C:C,0,1)="Hutang"),INDEX(Kode!A:A,0,1),"") | G12: =IF(OR(INDEX(Akun!C:C,0,1)="Db",INDEX(Akun!C:C,0,1)="Kr"),INDEX(Akun!A:A,0,1),"") -> 1-101-011
F13: =IF(OR(INDEX(Kode!C:C,0,1)="Piutang",INDEX(Kode!C:C,0,1)="Hutang"),INDEX(Kode!A:A,0,1),"") | G13: =IF(OR(INDEX(Akun!C:C,0,1)="Db",INDEX(Akun!C:C,0,1)="Kr"),INDEX(Akun!A:A,0,1),"") -> 1-101-012
F14: =IF(OR(INDEX(Kode!C:C,0,1)="Piutang",INDEX(Kode!C:C,0,1)="Hutang"),INDEX(Kode!A:A,0,1),"") | G14: =IF(OR(INDEX(Akun!C:C,0,1)="Db",INDEX(Akun!C:C,0,1)="Kr"),INDEX(Akun!A:A,0,1),"") -> 1-101-013
F15: =IF(OR(INDEX(Kode!C:C,0,1)="Piutang",INDEX(Kode!C:C,0,1)="Hutang"),INDEX(Kode!A:A,0,1),"") | G15: =IF(OR(INDEX(Akun!C:C,0,1)="Db",INDEX(Akun!C:C,0,1)="Kr"),INDEX(Akun!A:A,0,1),"") -> 1-101-100
F16: =IF(OR(INDEX(Kode!C:C,0,1)="Piutang",INDEX(Kode!C:C,0,1)="Hutang"),INDEX(Kode!A:A,0,1),"") | G16: =IF(OR(INDEX(Akun!C:C,0,1)="Db",INDEX(Akun!C:C,0,1)="Kr"),INDEX(Akun!A:A,0,1),"") -> 1-101-101
F17: =IF(OR(INDEX(Kode!C:C,0,1)="Piutang",INDEX(Kode!C:C,0,1)="Hutang"),INDEX(Kode!A:A,0,1),"") | G17: =IF(OR(INDEX(Akun!C:C,0,1)="Db",INDEX(Akun!C:C,0,1)="Kr"),INDEX(Akun!A:A,0,1),"") -> 1-101-200
